<sdf version='1.6'>
  <world name='default'>
    <light name='sun' type='directional'>
      <cast_shadows>1</cast_shadows>
      <pose frame=''>0 0 10 0 -0 0</pose>
      <diffuse>0.8 0.8 0.8 1</diffuse>
      <specular>0.2 0.2 0.2 1</specular>
      <attenuation>
        <range>1000</range>
        <constant>0.9</constant>
        <linear>0.01</linear>
        <quadratic>0.001</quadratic>
      </attenuation>
      <direction>-0.5 0.1 -0.9</direction>
    </light>
    <model name='ground_plane'>
      <static>1</static>
      <link name='link'>
        <collision name='collision'>
          <geometry>
            <plane>
              <normal>0 0 1</normal>
              <size>100 100</size>
            </plane>
          </geometry>
          <surface>
            <contact>
              <collide_bitmask>65535</collide_bitmask>
              <ode/>
            </contact>
            <friction>
              <ode>
                <mu>100</mu>
                <mu2>50</mu2>
              </ode>
              <torsional>
                <ode/>
              </torsional>
            </friction>
            <bounce/>
          </surface>
          <max_contacts>10</max_contacts>
        </collision>
        <visual name='visual'>
          <cast_shadows>0</cast_shadows>
          <geometry>
            <plane>
              <normal>0 0 1</normal>
              <size>100 100</size>
            </plane>
          </geometry>
          <material>
            <script>
              <uri>file://media/materials/scripts/gazebo.material</uri>
              <name>Gazebo/Grey</name>
            </script>
          </material>
        </visual>
        <self_collide>0</self_collide>
        <kinematic>0</kinematic>
      </link>
    </model>
    <gravity>0 0 -9.8</gravity>
    <magnetic_field>6e-06 2.3e-05 -4.2e-05</magnetic_field>
    <atmosphere type='adiabatic'/>
    <physics name='default_physics' default='0' type='ode'>
      <max_step_size>0.001</max_step_size>
      <real_time_factor>1</real_time_factor>
      <real_time_update_rate>1000</real_time_update_rate>
    </physics>
    <scene>
      <ambient>0.4 0.4 0.4 1</ambient>
      <background>0.7 0.7 0.7 1</background>
      <shadows>1</shadows>
    </scene>
    <spherical_coordinates>
      <surface_model>EARTH_WGS84</surface_model>
      <latitude_deg>0</latitude_deg>
      <longitude_deg>0</longitude_deg>
      <elevation>0</elevation>
      <heading_deg>0</heading_deg>
    </spherical_coordinates>
    <model name='kinect'>
      <static>1</static>
      <link name='link'>
        <inertial>
          <mass>0.1</mass>
        </inertial>
        <collision name='collision'>
          <geometry>
            <box>
              <size>0.073 0.276 0.072</size>
            </box>
          </geometry>
          <max_contacts>10</max_contacts>
          <surface>
            <contact>
              <ode/>
            </contact>
            <bounce/>
            <friction>
              <torsional>
                <ode/>
              </torsional>
              <ode/>
            </friction>
          </surface>
        </collision>
        <visual name='visual'>
          <geometry>
            <mesh>
              <uri>model://kinect/meshes/kinect.dae</uri>
            </mesh>
          </geometry>
        </visual>
        <sensor name='camera' type='depth'>
          <update_rate>20</update_rate>
          <camera name='__default__'>
            <horizontal_fov>1.0472</horizontal_fov>
            <image>
              <width>1920</width>
              <height>1080</height>
              <format>R8G8B8</format>
            </image>
            <clip>
              <near>0.05</near>
              <far>3</far>
            </clip>
          </camera>
          <plugin name='camera_plugin' filename='libgazebo_ros_openni_kinect.so'>
            <baseline>0.2</baseline>
            <alwaysOn>true</alwaysOn>
            <updateRate>0.0</updateRate>
            <cameraName>camera_ir</cameraName>
            <cameraName>camera</cameraName>
            <imageTopicName>/camera/rgb/image_rect_color</imageTopicName>
            <cameraInfoTopicName>/camera/rgb/camera_info</cameraInfoTopicName>
            <depthImageTopicName>/camera/depth_registered/image_raw</depthImageTopicName>
            <depthImageCameraInfoTopicName>/camera/depth_registered/camera_info</depthImageCameraInfoTopicName>
            <pointCloudTopicName>/camera/depth_registered/points</pointCloudTopicName>
            <frameName>camera_link</frameName>
            <pointCloudCutoff>0.05</pointCloudCutoff>
            <distortionK1>0.037507754157959365</distortionK1>
            <distortionK2>0.021367495518717992</distortionK2>
            <distortionK3>-0.0083557962473024168</distortionK3>
            <distortionT1>-0.0054151782272329769</distortionT1>
            <distortionT2>-0.14277150062748054</distortionT2>
            <CxPrime>0</CxPrime>
            <Cx>939.205</Cx>
            <Cy>518.124</Cy>
            <focalLength>1043.362</focalLength>
            <hackBaseline>0</hackBaseline>
            <robotNamespace>/</robotNamespace>
          </plugin>
        </sensor>
        <self_collide>0</self_collide>
        <kinematic>0</kinematic>
      </link>
      <pose frame=''>0.120176 -0.20872 1.276999 1.570798 1.570788 1.570788</pose>
    </model>
    <model name='robot_on_table'>
      <link name='table_base'>
        <pose frame=''>0 0 0.273 0 -0 0</pose>
        <inertial>
          <pose frame=''>0.018512 -0.047982 0.652828 0 -0 0</pose>
          <mass>4.03703e+06</mass>
          <inertia>
            <ixx>966458</ixx>
            <ixy>-0.0591523</ixy>
            <ixz>0.0582311</ixz>
            <iyy>1.0825e+06</iyy>
            <iyz>-270361</iyz>
            <izz>806693</izz>
          </inertia>
        </inertial>
        <collision name='table_base_collision'>
          <pose frame=''>0 0 0 0 -0 0</pose>
          <geometry>
            <mesh>
              <scale>1 1 1</scale>
              <uri>/home/xkx/JCAR_V1_ws/src/robot_grasp/models/table/meshes/table_base.STL</uri>
            </mesh>
          </geometry>
          <surface>
            <contact>
              <ode/>
            </contact>
            <friction>
              <ode/>
              <torsional>
                <ode/>
              </torsional>
            </friction>
            <bounce/>
          </surface>
          <max_contacts>10</max_contacts>
        </collision>
        <collision name='table_base_fixed_joint_lump__table_top_collision_1'>
          <pose frame=''>0.018512 0.221508 0.435076 1.5708 -0 0</pose>
          <geometry>
            <box>
              <size>1.05 0.015 0.005</size>
            </box>
          </geometry>
          <surface>
            <contact>
              <ode/>
            </contact>
            <friction>
              <ode/>
              <torsional>
                <ode/>
              </torsional>
            </friction>
            <bounce/>
          </surface>
          <max_contacts>10</max_contacts>
        </collision>
        <collision name='table_base_fixed_joint_lump__table_top_collision_2'>
          <pose frame=''>0.541012 -0.175992 0.435076 1.5708 -0 0</pose>
          <geometry>
            <box>
              <size>0.005 0.015 0.8</size>
            </box>
          </geometry>
          <surface>
            <contact>
              <ode/>
            </contact>
            <friction>
              <ode/>
              <torsional>
                <ode/>
              </torsional>
            </friction>
            <bounce/>
          </surface>
          <max_contacts>10</max_contacts>
        </collision>
        <collision name='table_base_fixed_joint_lump__table_top_collision_3'>
          <pose frame=''>0.018512 -0.175992 0.397576 1.5708 -0 0</pose>
          <geometry>
            <mesh>
              <scale>1 1 1</scale>
              <uri>/home/xkx/JCAR_V1_ws/src/robot_grasp/models/table/meshes/table_top.STL</uri>
            </mesh>
          </geometry>
          <surface>
            <contact>
              <ode/>
            </contact>
            <friction>
              <ode/>
              <torsional>
                <ode/>
              </torsional>
            </friction>
            <bounce/>
          </surface>
          <max_contacts>10</max_contacts>
        </collision>
        <collision name='table_base_fixed_joint_lump__basket_collision_4'>
          <pose frame=''>0.268512 -0.225992 0.457576 1.5708 -0 0</pose>
          <geometry>
            <mesh>
              <scale>0.001 0.001 0.001</scale>
              <uri>/home/xkx/JCAR_V1_ws/src/robot_grasp/models/grasp_object/basket.dae</uri>
            </mesh>
          </geometry>
          <surface>
            <contact>
              <ode/>
            </contact>
            <friction>
              <ode/>
              <torsional>
                <ode/>
              </torsional>
            </friction>
            <bounce/>
          </surface>
          <max_contacts>10</max_contacts>
        </collision>
        <collision name='table_base_fixed_joint_lump__basket2_collision_5'>
          <pose frame=''>-0.181488 -0.225992 0.457576 1.5708 -0 0</pose>
          <geometry>
            <mesh>
              <scale>0.001 0.001 0.001</scale>
              <uri>/home/xkx/JCAR_V1_ws/src/robot_grasp/models/grasp_object/basket.dae</uri>
            </mesh>
          </geometry>
          <surface>
            <contact>
              <ode/>
            </contact>
            <friction>
              <ode/>
              <torsional>
                <ode/>
              </torsional>
            </friction>
            <bounce/>
          </surface>
          <max_contacts>10</max_contacts>
        </collision>
        <collision name='table_base_fixed_joint_lump__kinect_support_collision_6'>
          <pose frame=''>0.118512 -0.475992 0.587576 1.5708 0 -1.5708</pose>
          <geometry>
            <mesh>
              <scale>0.001 0.001 0.001</scale>
              <uri>/home/xkx/JCAR_V1_ws/src/robot_grasp/models/grasp_object/meshes/kinect_support.dae</uri>
            </mesh>
          </geometry>
          <surface>
            <contact>
              <ode/>
            </contact>
            <friction>
              <ode/>
              <torsional>
                <ode/>
              </torsional>
            </friction>
            <bounce/>
          </surface>
          <max_contacts>10</max_contacts>
        </collision>
        <collision name='table_base_fixed_joint_lump__arm_stand_collision_7'>
          <pose frame=''>0.414399 0.098639 0.430576 1.5708 0 2.38159</pose>
          <geometry>
            <mesh>
              <scale>1 1 1</scale>
              <uri>/home/xkx/JCAR_V1_ws/src/robot_grasp/models/table/meshes/arm_stand.STL</uri>
            </mesh>
          </geometry>
          <surface>
            <contact>
              <ode/>
            </contact>
            <friction>
              <ode/>
              <torsional>
                <ode/>
              </torsional>
            </friction>
            <bounce/>
          </surface>
          <max_contacts>10</max_contacts>
        </collision>
        <collision name='table_base_fixed_joint_lump__root_collision_8'>
          <pose frame=''>0.414399 0.098639 0.510576 0 -0 2.43159</pose>
          <geometry>
            <box>
              <size>1e-05 1e-05 1e-05</size>
            </box>
          </geometry>
          <max_contacts>10</max_contacts>
          <surface>
            <contact>
              <ode/>
            </contact>
            <bounce/>
            <friction>
              <torsional>
                <ode/>
              </torsional>
              <ode/>
            </friction>
          </surface>
        </collision>
        <collision name='table_base_fixed_joint_lump__j2s7s300_link_base_collision_9'>
          <pose frame=''>0.414399 0.098639 0.510576 0 -0 2.43159</pose>
          <geometry>
            <mesh>
              <scale>1 1 1</scale>
              <uri>/home/xkx/JCAR_V1_ws/src/kinova_description/meshes/base.dae</uri>
            </mesh>
          </geometry>
          <max_contacts>10</max_contacts>
          <surface>
            <contact>
              <ode/>
            </contact>
            <bounce/>
            <friction>
              <torsional>
                <ode/>
              </torsional>
              <ode/>
            </friction>
          </surface>
        </collision>
        <visual name='table_base_visual'>
          <pose frame=''>0 0 0 0 -0 0</pose>
          <geometry>
            <mesh>
              <scale>1 1 1</scale>
              <uri>/home/xkx/JCAR_V1_ws/src/robot_grasp/models/table/meshes/table_base.STL</uri>
            </mesh>
          </geometry>
          <material>
            <script>
              <name>Gazebo/FlatBlack</name>
              <uri>file://media/materials/scripts/gazebo.material</uri>
            </script>
          </material>
        </visual>
        <visual name='table_base_fixed_joint_lump__table_top_visual_1'>
          <pose frame=''>0.018512 -0.175992 0.397576 1.5708 -0 0</pose>
          <geometry>
            <mesh>
              <scale>1 1 1</scale>
              <uri>/home/xkx/JCAR_V1_ws/src/robot_grasp/models/table/meshes/table_top.STL</uri>
            </mesh>
          </geometry>
          <material>
            <script>
              <name>Gazebo/White</name>
              <uri>file://media/materials/scripts/gazebo.material</uri>
            </script>
          </material>
        </visual>
        <visual name='table_base_fixed_joint_lump__table_top_visual_2'>
          <pose frame=''>0.018512 0.221508 0.435076 1.5708 -0 0</pose>
          <geometry>
            <box>
              <size>1.05 0.015 0.005</size>
            </box>
          </geometry>
          <material>
            <script>
              <name>Gazebo/White</name>
              <uri>file://media/materials/scripts/gazebo.material</uri>
            </script>
          </material>
        </visual>
        <visual name='table_base_fixed_joint_lump__table_top_visual_3'>
          <pose frame=''>0.541012 -0.175992 0.435076 1.5708 -0 0</pose>
          <geometry>
            <box>
              <size>0.005 0.015 0.8</size>
            </box>
          </geometry>
          <material>
            <script>
              <name>Gazebo/White</name>
              <uri>file://media/materials/scripts/gazebo.material</uri>
            </script>
          </material>
        </visual>
        <visual name='table_base_fixed_joint_lump__basket_visual_4'>
          <pose frame=''>0.268512 -0.225992 0.457576 1.5708 -0 0</pose>
          <geometry>
            <mesh>
              <scale>0.001 0.001 0.001</scale>
              <uri>/home/xkx/JCAR_V1_ws/src/robot_grasp/models/grasp_object/basket.dae</uri>
            </mesh>
          </geometry>
          <material>
            <script>
              <name>Gazebo/Green</name>
              <uri>file://media/materials/scripts/gazebo.material</uri>
            </script>
          </material>
        </visual>
        <visual name='table_base_fixed_joint_lump__basket2_visual_5'>
          <pose frame=''>-0.181488 -0.225992 0.457576 1.5708 -0 0</pose>
          <geometry>
            <mesh>
              <scale>0.001 0.001 0.001</scale>
              <uri>/home/xkx/JCAR_V1_ws/src/robot_grasp/models/grasp_object/basket.dae</uri>
            </mesh>
          </geometry>
          <material>
            <script>
              <name>Gazebo/Blue</name>
              <uri>file://media/materials/scripts/gazebo.material</uri>
            </script>
          </material>
        </visual>
        <visual name='table_base_fixed_joint_lump__kinect_support_visual_6'>
          <pose frame=''>0.118512 -0.475992 0.587576 1.5708 0 -1.5708</pose>
          <geometry>
            <mesh>
              <scale>0.001 0.001 0.001</scale>
              <uri>/home/xkx/JCAR_V1_ws/src/robot_grasp/models/table/meshes/kinect_support.dae</uri>
            </mesh>
          </geometry>
          <material>
            <script>
              <name>Gazebo/Black</name>
              <uri>file://media/materials/scripts/gazebo.material</uri>
            </script>
          </material>
        </visual>
        <visual name='table_base_fixed_joint_lump__arm_stand_visual_7'>
          <pose frame=''>0.414399 0.098639 0.430576 1.5708 0 2.38159</pose>
          <geometry>
            <mesh>
              <scale>1 1 1</scale>
              <uri>/home/xkx/JCAR_V1_ws/src/robot_grasp/models/table/meshes/arm_stand.STL</uri>
            </mesh>
          </geometry>
          <material>
            <script>
              <name>Gazebo/FlatBlack</name>
              <uri>file://media/materials/scripts/gazebo.material</uri>
            </script>
          </material>
        </visual>
        <visual name='table_base_fixed_joint_lump__root_visual_8'>
          <pose frame=''>0.414399 0.098639 0.510576 0 -0 2.43159</pose>
          <geometry>
            <box>
              <size>1e-05 1e-05 1e-05</size>
            </box>
          </geometry>
        </visual>
        <visual name='table_base_fixed_joint_lump__j2s7s300_link_base_visual_9'>
          <pose frame=''>0.414399 0.098639 0.510576 0 -0 2.43159</pose>
          <geometry>
            <mesh>
              <scale>1 1 1</scale>
              <uri>/home/xkx/JCAR_V1_ws/src/kinova_description/meshes/base.dae</uri>
            </mesh>
          </geometry>
        </visual>
        <velocity_decay/>
        <velocity_decay/>
        <velocity_decay/>
        <velocity_decay/>
        <velocity_decay/>
        <gravity>1</gravity>
        <velocity_decay/>
        <self_collide>0</self_collide>
        <kinematic>0</kinematic>
      </link>
      <joint name='j0' type='fixed'>
        <child>table_base</child>
        <parent>world</parent>
      </joint>
      <link name='j2s7s300_link_1'>
        <pose frame=''>0.414399 0.098639 0.940326 3.14159 -0 -0.71</pose>
        <inertial>
          <pose frame=''>0 -0.002 -0.0605 0 -0 0</pose>
          <mass>0.7477</mass>
          <inertia>
            <ixx>0.00152032</ixx>
            <ixy>0</ixy>
            <ixz>0</ixz>
            <iyy>0.00152032</iyy>
            <iyz>0</iyz>
            <izz>0.00059816</izz>
          </inertia>
        </inertial>
        <collision name='j2s7s300_link_1_collision'>
          <pose frame=''>0 0 0 0 -0 0</pose>
          <geometry>
            <mesh>
              <scale>1 1 1</scale>
              <uri>/home/xkx/JCAR_V1_ws/src/kinova_description/meshes/shoulder.dae</uri>
            </mesh>
          </geometry>
          <max_contacts>10</max_contacts>
          <surface>
            <contact>
              <ode/>
            </contact>
            <bounce/>
            <friction>
              <torsional>
                <ode/>
              </torsional>
              <ode/>
            </friction>
          </surface>
        </collision>
        <visual name='j2s7s300_link_1_visual'>
          <pose frame=''>0 0 0 0 -0 0</pose>
          <geometry>
            <mesh>
              <scale>1 1 1</scale>
              <uri>/home/xkx/JCAR_V1_ws/src/kinova_description/meshes/shoulder.dae</uri>
            </mesh>
          </geometry>
        </visual>
        <visual name='j2s7s300_link_1_visual_1'>
          <pose frame=''>0 0 0 0 -0 0</pose>
          <geometry>
            <mesh>
              <scale>1 1 1</scale>
              <uri>/home/xkx/JCAR_V1_ws/src/kinova_description/meshes/ring_big.STL</uri>
            </mesh>
          </geometry>
        </visual>
        <self_collide>0</self_collide>
        <kinematic>0</kinematic>
      </link>
      <joint name='j2s7s300_joint_1' type='revolute'>
        <child>j2s7s300_link_1</child>
        <parent>table_base</parent>
        <axis>
          <xyz>0 0 -1</xyz>
          <limit>
            <lower>-1e+16</lower>
            <upper>1e+16</upper>
          </limit>
          <dynamics>
            <damping>0</damping>
            <friction>0</friction>
            <spring_reference>0</spring_reference>
            <spring_stiffness>0</spring_stiffness>
          </dynamics>
          <use_parent_model_frame>1</use_parent_model_frame>
        </axis>
      </joint>
      <link name='j2s7s300_link_2'>
        <pose frame=''>0.413356 0.097425 1.05908 1.5708 -0 2.43159</pose>
        <inertial>
          <pose frame=''>0 -0.103563 0 0 -0 0</pose>
          <mass>0.8447</mass>
          <inertia>
            <ixx>0.00247074</ixx>
            <ixy>0</ixy>
            <ixz>0</ixz>
            <iyy>0.000380115</iyy>
            <iyz>0</iyz>
            <izz>0.00247074</izz>
          </inertia>
        </inertial>
        <collision name='j2s7s300_link_2_collision'>
          <pose frame=''>0 0 0 0 -0 0</pose>
          <geometry>
            <mesh>
              <scale>1 1 1</scale>
              <uri>/home/xkx/JCAR_V1_ws/src/kinova_description/meshes/arm_half_1.dae</uri>
            </mesh>
          </geometry>
          <max_contacts>10</max_contacts>
          <surface>
            <contact>
              <ode/>
            </contact>
            <bounce/>
            <friction>
              <torsional>
                <ode/>
              </torsional>
              <ode/>
            </friction>
          </surface>
        </collision>
        <visual name='j2s7s300_link_2_visual'>
          <pose frame=''>0 0 0 0 -0 0</pose>
          <geometry>
            <mesh>
              <scale>1 1 1</scale>
              <uri>/home/xkx/JCAR_V1_ws/src/kinova_description/meshes/arm_half_1.dae</uri>
            </mesh>
          </geometry>
        </visual>
        <visual name='j2s7s300_link_2_visual_1'>
          <pose frame=''>0 0 0 0 -0 0</pose>
          <geometry>
            <mesh>
              <scale>1 1 1</scale>
              <uri>/home/xkx/JCAR_V1_ws/src/kinova_description/meshes/ring_big.STL</uri>
            </mesh>
          </geometry>
        </visual>
        <self_collide>0</self_collide>
        <kinematic>0</kinematic>
      </link>
      <joint name='j2s7s300_joint_2' type='revolute'>
        <child>j2s7s300_link_2</child>
        <parent>j2s7s300_link_1</parent>
        <axis>
          <xyz>0.651834 0.758362 0</xyz>
          <limit>
            <lower>0.523599</lower>
            <upper>5.75959</upper>
            <effort>2000</effort>
            <velocity>1</velocity>
          </limit>
          <dynamics>
            <damping>0</damping>
            <friction>0</friction>
            <spring_reference>0</spring_reference>
            <spring_stiffness>0</spring_stiffness>
          </dynamics>
          <use_parent_model_frame>1</use_parent_model_frame>
        </axis>
      </joint>
      <link name='j2s7s300_link_3'>
        <pose frame=''>0.413356 0.097425 0.854076 0 -0 2.43159</pose>
        <inertial>
          <pose frame=''>0 0 -0.102245 0 -0 0</pose>
          <mass>0.8447</mass>
          <inertia>
            <ixx>0.00247074</ixx>
            <ixy>0</ixy>
            <ixz>0</ixz>
            <iyy>0.00247074</iyy>
            <iyz>0</iyz>
            <izz>0.000380115</izz>
          </inertia>
        </inertial>
        <collision name='j2s7s300_link_3_collision'>
          <pose frame=''>0 0 0 0 -0 0</pose>
          <geometry>
            <mesh>
              <scale>1 1 1</scale>
              <uri>/home/xkx/JCAR_V1_ws/src/kinova_description/meshes/arm_half_2.dae</uri>
            </mesh>
          </geometry>
          <max_contacts>10</max_contacts>
          <surface>
            <contact>
              <ode/>
            </contact>
            <bounce/>
            <friction>
              <torsional>
                <ode/>
              </torsional>
              <ode/>
            </friction>
          </surface>
        </collision>
        <visual name='j2s7s300_link_3_visual'>
          <pose frame=''>0 0 0 0 -0 0</pose>
          <geometry>
            <mesh>
              <scale>1 1 1</scale>
              <uri>/home/xkx/JCAR_V1_ws/src/kinova_description/meshes/arm_half_2.dae</uri>
            </mesh>
          </geometry>
        </visual>
        <visual name='j2s7s300_link_3_visual_1'>
          <pose frame=''>0 0 0 0 -0 0</pose>
          <geometry>
            <mesh>
              <scale>1 1 1</scale>
              <uri>/home/xkx/JCAR_V1_ws/src/kinova_description/meshes/ring_big.STL</uri>
            </mesh>
          </geometry>
        </visual>
        <self_collide>0</self_collide>
        <kinematic>0</kinematic>
      </link>
      <joint name='j2s7s300_joint_3' type='revolute'>
        <child>j2s7s300_link_3</child>
        <parent>j2s7s300_link_2</parent>
        <axis>
          <xyz>0 0 1</xyz>
          <limit>
            <lower>-1e+16</lower>
            <upper>1e+16</upper>
          </limit>
          <dynamics>
            <damping>0</damping>
            <friction>0</friction>
            <spring_reference>0</spring_reference>
            <spring_stiffness>0</spring_stiffness>
          </dynamics>
          <use_parent_model_frame>1</use_parent_model_frame>
        </axis>
      </joint>
      <link name='j2s7s300_link_4'>
        <pose frame=''>0.413356 0.097425 0.649076 1.5708 -0 -0.71</pose>
        <inertial>
          <pose frame=''>0 0.081 -0.0086 0 -0 0</pose>
          <mass>0.6763</mass>
          <inertia>
            <ixx>0.00142022</ixx>
            <ixy>0</ixy>
            <ixz>0</ixz>
            <iyy>0.000304335</iyy>
            <iyz>0</iyz>
            <izz>0.00142022</izz>
          </inertia>
        </inertial>
        <collision name='j2s7s300_link_4_collision'>
          <pose frame=''>0 0 0 0 -0 0</pose>
          <geometry>
            <mesh>
              <scale>1 1 1</scale>
              <uri>/home/xkx/JCAR_V1_ws/src/kinova_description/meshes/forearm.dae</uri>
            </mesh>
          </geometry>
          <max_contacts>10</max_contacts>
          <surface>
            <contact>
              <ode/>
            </contact>
            <bounce/>
            <friction>
              <torsional>
                <ode/>
              </torsional>
              <ode/>
            </friction>
          </surface>
        </collision>
        <visual name='j2s7s300_link_4_visual'>
          <pose frame=''>0 0 0 0 -0 0</pose>
          <geometry>
            <mesh>
              <scale>1 1 1</scale>
              <uri>/home/xkx/JCAR_V1_ws/src/kinova_description/meshes/forearm.dae</uri>
            </mesh>
          </geometry>
        </visual>
        <visual name='j2s7s300_link_4_visual_1'>
          <pose frame=''>0 0 0 0 -0 0</pose>
          <geometry>
            <mesh>
              <scale>1 1 1</scale>
              <uri>/home/xkx/JCAR_V1_ws/src/kinova_description/meshes/ring_small.STL</uri>
            </mesh>
          </geometry>
        </visual>
        <self_collide>0</self_collide>
        <kinematic>0</kinematic>
      </link>
      <joint name='j2s7s300_joint_4' type='revolute'>
        <child>j2s7s300_link_4</child>
        <parent>j2s7s300_link_3</parent>
        <axis>
          <xyz>-0.651834 -0.758362 0</xyz>
          <limit>
            <lower>0.523599</lower>
            <upper>5.75959</upper>
            <effort>2000</effort>
            <velocity>1</velocity>
          </limit>
          <dynamics>
            <damping>0</damping>
            <friction>0</friction>
            <spring_reference>0</spring_reference>
            <spring_stiffness>0</spring_stiffness>
          </dynamics>
          <use_parent_model_frame>1</use_parent_model_frame>
        </axis>
      </joint>
      <link name='j2s7s300_link_5'>
        <pose frame=''>0.420787 0.106071 0.856376 -3.14159 0 2.43159</pose>
        <inertial>
          <pose frame=''>0 0.002885 -0.054193 0 -0 0</pose>
          <mass>0.463</mass>
          <inertia>
            <ixx>0.000432132</ixx>
            <ixy>0</ixy>
            <ixz>0</ixz>
            <iyy>0.000432132</iyy>
            <iyz>0</iyz>
            <izz>9.26e-05</izz>
          </inertia>
        </inertial>
        <collision name='j2s7s300_link_5_collision'>
          <pose frame=''>0 0 0 0 -0 0</pose>
          <geometry>
            <mesh>
              <scale>1 1 1</scale>
              <uri>/home/xkx/JCAR_V1_ws/src/kinova_description/meshes/wrist_spherical_1.dae</uri>
            </mesh>
          </geometry>
          <max_contacts>10</max_contacts>
          <surface>
            <contact>
              <ode/>
            </contact>
            <bounce/>
            <friction>
              <torsional>
                <ode/>
              </torsional>
              <ode/>
            </friction>
          </surface>
        </collision>
        <visual name='j2s7s300_link_5_visual'>
          <pose frame=''>0 0 0 0 -0 0</pose>
          <geometry>
            <mesh>
              <scale>1 1 1</scale>
              <uri>/home/xkx/JCAR_V1_ws/src/kinova_description/meshes/wrist_spherical_1.dae</uri>
            </mesh>
          </geometry>
        </visual>
        <visual name='j2s7s300_link_5_visual_1'>
          <pose frame=''>0 0 0 0 -0 0</pose>
          <geometry>
            <mesh>
              <scale>1 1 1</scale>
              <uri>/home/xkx/JCAR_V1_ws/src/kinova_description/meshes/ring_small.STL</uri>
            </mesh>
          </geometry>
        </visual>
        <self_collide>0</self_collide>
        <kinematic>0</kinematic>
      </link>
      <joint name='j2s7s300_joint_5' type='revolute'>
        <child>j2s7s300_link_5</child>
        <parent>j2s7s300_link_4</parent>
        <axis>
          <xyz>0 0 -1</xyz>
          <limit>
            <lower>-1e+16</lower>
            <upper>1e+16</upper>
          </limit>
          <dynamics>
            <damping>0</damping>
            <friction>0</friction>
            <spring_reference>0</spring_reference>
            <spring_stiffness>0</spring_stiffness>
          </dynamics>
          <use_parent_model_frame>1</use_parent_model_frame>
        </axis>
      </joint>
      <link name='j2s7s300_link_6'>
        <pose frame=''>0.420787 0.106071 0.960126 -1.5708 0 -0.71</pose>
        <inertial>
          <pose frame=''>0 0.049721 -0.002856 0 -0 0</pose>
          <mass>0.463</mass>
          <inertia>
            <ixx>0.000432132</ixx>
            <ixy>0</ixy>
            <ixz>0</ixz>
            <iyy>9.26e-05</iyy>
            <iyz>0</iyz>
            <izz>0.000432132</izz>
          </inertia>
        </inertial>
        <collision name='j2s7s300_link_6_collision'>
          <pose frame=''>0 0 0 0 -0 0</pose>
          <geometry>
            <mesh>
              <scale>1 1 1</scale>
              <uri>/home/xkx/JCAR_V1_ws/src/kinova_description/meshes/wrist_spherical_2.dae</uri>
            </mesh>
          </geometry>
          <max_contacts>10</max_contacts>
          <surface>
            <contact>
              <ode/>
            </contact>
            <bounce/>
            <friction>
              <torsional>
                <ode/>
              </torsional>
              <ode/>
            </friction>
          </surface>
        </collision>
        <visual name='j2s7s300_link_6_visual'>
          <pose frame=''>0 0 0 0 -0 0</pose>
          <geometry>
            <mesh>
              <scale>1 1 1</scale>
              <uri>/home/xkx/JCAR_V1_ws/src/kinova_description/meshes/wrist_spherical_2.dae</uri>
            </mesh>
          </geometry>
        </visual>
        <visual name='j2s7s300_link_6_visual_1'>
          <pose frame=''>0 0 0 0 -0 0</pose>
          <geometry>
            <mesh>
              <scale>1 1 1</scale>
              <uri>/home/xkx/JCAR_V1_ws/src/kinova_description/meshes/ring_small.STL</uri>
            </mesh>
          </geometry>
        </visual>
        <self_collide>0</self_collide>
        <kinematic>0</kinematic>
      </link>
      <joint name='j2s7s300_joint_6' type='revolute'>
        <child>j2s7s300_link_6</child>
        <parent>j2s7s300_link_5</parent>
        <axis>
          <xyz>0.651834 0.758362 0</xyz>
          <limit>
            <lower>0.523599</lower>
            <upper>5.75959</upper>
            <effort>2000</effort>
            <velocity>1</velocity>
          </limit>
          <dynamics>
            <damping>0</damping>
            <friction>0</friction>
            <spring_reference>0</spring_reference>
            <spring_stiffness>0</spring_stiffness>
          </dynamics>
          <use_parent_model_frame>1</use_parent_model_frame>
        </axis>
      </joint>
      <link name='j2s7s300_link_7'>
        <pose frame=''>0.420787 0.106071 0.856376 0 -0 2.43159</pose>
        <inertial>
          <pose frame=''>0 0 -0.06 0 -0 0</pose>
          <mass>0.727</mass>
          <inertia>
            <ixx>0.000345324</ixx>
            <ixy>0</ixy>
            <ixz>0</ixz>
            <iyy>0.000345324</iyy>
            <iyz>0</iyz>
            <izz>0.0005816</izz>
          </inertia>
        </inertial>
        <collision name='j2s7s300_link_7_collision'>
          <pose frame=''>0 0 0 0 -0 0</pose>
          <geometry>
            <mesh>
              <scale>1 1 1</scale>
              <uri>/home/xkx/JCAR_V1_ws/src/kinova_description/meshes/hand_3finger.dae</uri>
            </mesh>
          </geometry>
          <max_contacts>10</max_contacts>
          <surface>
            <contact>
              <ode/>
            </contact>
            <bounce/>
            <friction>
              <torsional>
                <ode/>
              </torsional>
              <ode/>
            </friction>
          </surface>
        </collision>
        <collision name='j2s7s300_link_7_fixed_joint_lump__j2s7s300_end_effector_collision_1'>
          <pose frame=''>0 0 -0.16 -3.14159 -0 0</pose>
          <geometry>
            <box>
              <size>1e-05 1e-05 1e-05</size>
            </box>
          </geometry>
          <max_contacts>10</max_contacts>
          <surface>
            <contact>
              <ode/>
            </contact>
            <bounce/>
            <friction>
              <torsional>
                <ode/>
              </torsional>
              <ode/>
            </friction>
          </surface>
        </collision>
        <visual name='j2s7s300_link_7_visual'>
          <pose frame=''>0 0 0 0 -0 0</pose>
          <geometry>
            <mesh>
              <scale>1 1 1</scale>
              <uri>/home/xkx/JCAR_V1_ws/src/kinova_description/meshes/hand_3finger.dae</uri>
            </mesh>
          </geometry>
        </visual>
        <visual name='j2s7s300_link_7_visual_1'>
          <pose frame=''>0 0 0 0 -0 0</pose>
          <geometry>
            <mesh>
              <scale>1 1 1</scale>
              <uri>/home/xkx/JCAR_V1_ws/src/kinova_description/meshes/ring_small.STL</uri>
            </mesh>
          </geometry>
        </visual>
        <visual name='j2s7s300_link_7_fixed_joint_lump__j2s7s300_end_effector_visual_2'>
          <pose frame=''>0 0 -0.16 -3.14159 -0 0</pose>
          <geometry>
            <box>
              <size>1e-05 1e-05 1e-05</size>
            </box>
          </geometry>
        </visual>
        <self_collide>0</self_collide>
        <kinematic>0</kinematic>
      </link>
      <joint name='j2s7s300_joint_7' type='revolute'>
        <child>j2s7s300_link_7</child>
        <parent>j2s7s300_link_6</parent>
        <axis>
          <xyz>0 0 1</xyz>
          <limit>
            <lower>-1e+16</lower>
            <upper>1e+16</upper>
          </limit>
          <dynamics>
            <damping>0</damping>
            <friction>0</friction>
            <spring_reference>0</spring_reference>
            <spring_stiffness>0</spring_stiffness>
          </dynamics>
          <use_parent_model_frame>1</use_parent_model_frame>
        </axis>
      </joint>
      <link name='j2s7s300_link_finger_1'>
        <pose frame=''>0.398295 0.084183 0.741706 -1.5708 0.649262 -2.49198</pose>
        <inertial>
          <pose frame=''>0.044 -0.0015 0 0 -0 0</pose>
          <mass>0.02</mass>
          <inertia>
            <ixx>1.62499e-06</ixx>
            <ixy>6.6e-07</ixy>
            <ixz>0</ixz>
            <iyy>1.126e-05</iyy>
            <iyz>0</iyz>
            <izz>9.885e-06</izz>
          </inertia>
        </inertial>
        <collision name='j2s7s300_link_finger_1_collision'>
          <pose frame=''>0 0 0 0 -0 0</pose>
          <geometry>
            <mesh>
              <scale>1 1 1</scale>
              <uri>/home/xkx/JCAR_V1_ws/src/kinova_description/meshes/finger_proximal.dae</uri>
            </mesh>
          </geometry>
          <max_contacts>10</max_contacts>
          <surface>
            <contact>
              <ode/>
            </contact>
            <bounce/>
            <friction>
              <torsional>
                <ode/>
              </torsional>
              <ode/>
            </friction>
          </surface>
        </collision>
        <collision name='j2s7s300_link_finger_1_fixed_joint_lump__j2s7s300_link_finger_tip_1_collision_1'>
          <pose frame=''>0.044 -0.003 0 0 -0 0</pose>
          <geometry>
            <mesh>
              <scale>1 1 1</scale>
              <uri>/home/xkx/JCAR_V1_ws/src/kinova_description/meshes/finger_distal.dae</uri>
            </mesh>
          </geometry>
          <max_contacts>10</max_contacts>
          <surface>
            <contact>
              <ode/>
            </contact>
            <bounce/>
            <friction>
              <torsional>
                <ode/>
              </torsional>
              <ode/>
            </friction>
          </surface>
        </collision>
        <visual name='j2s7s300_link_finger_1_visual'>
          <pose frame=''>0 0 0 0 -0 0</pose>
          <geometry>
            <mesh>
              <scale>1 1 1</scale>
              <uri>/home/xkx/JCAR_V1_ws/src/kinova_description/meshes/finger_proximal.dae</uri>
            </mesh>
          </geometry>
        </visual>
        <visual name='j2s7s300_link_finger_1_fixed_joint_lump__j2s7s300_link_finger_tip_1_visual_1'>
          <pose frame=''>0.044 -0.003 0 0 -0 0</pose>
          <geometry>
            <mesh>
              <scale>1 1 1</scale>
              <uri>/home/xkx/JCAR_V1_ws/src/kinova_description/meshes/finger_distal.dae</uri>
            </mesh>
          </geometry>
        </visual>
        <self_collide>0</self_collide>
        <kinematic>0</kinematic>
      </link>
      <joint name='j2s7s300_joint_finger_1' type='revolute'>
        <child>j2s7s300_link_finger_1</child>
        <parent>j2s7s300_link_7</parent>
        <axis>
          <xyz>0.604877 -0.796319 0</xyz>
          <limit>
            <lower>0</lower>
            <upper>2</upper>
            <effort>2000</effort>
            <velocity>1</velocity>
          </limit>
          <dynamics>
            <spring_reference>0</spring_reference>
            <spring_stiffness>0</spring_stiffness>
          </dynamics>
          <use_parent_model_frame>1</use_parent_model_frame>
        </axis>
      </joint>
      <link name='j2s7s300_link_finger_2'>
        <pose frame=''>0.421551 0.141109 0.741556 -1.5708 0.649262 1.04545</pose>
        <inertial>
          <pose frame=''>0.044 -0.0015 0 0 -0 0</pose>
          <mass>0.02</mass>
          <inertia>
            <ixx>1.62499e-06</ixx>
            <ixy>6.6e-07</ixy>
            <ixz>0</ixz>
            <iyy>1.126e-05</iyy>
            <iyz>0</iyz>
            <izz>9.885e-06</izz>
          </inertia>
        </inertial>
        <collision name='j2s7s300_link_finger_2_collision'>
          <pose frame=''>0 0 0 0 -0 0</pose>
          <geometry>
            <mesh>
              <scale>1 1 1</scale>
              <uri>/home/xkx/JCAR_V1_ws/src/kinova_description/meshes/finger_proximal.dae</uri>
            </mesh>
          </geometry>
          <max_contacts>10</max_contacts>
          <surface>
            <contact>
              <ode/>
            </contact>
            <bounce/>
            <friction>
              <torsional>
                <ode/>
              </torsional>
              <ode/>
            </friction>
          </surface>
        </collision>
        <collision name='j2s7s300_link_finger_2_fixed_joint_lump__j2s7s300_link_finger_tip_2_collision_1'>
          <pose frame=''>0.044 -0.003 0 0 -0 0</pose>
          <geometry>
            <mesh>
              <scale>1 1 1</scale>
              <uri>/home/xkx/JCAR_V1_ws/src/kinova_description/meshes/finger_distal.dae</uri>
            </mesh>
          </geometry>
          <max_contacts>10</max_contacts>
          <surface>
            <contact>
              <ode/>
            </contact>
            <bounce/>
            <friction>
              <torsional>
                <ode/>
              </torsional>
              <ode/>
            </friction>
          </surface>
        </collision>
        <visual name='j2s7s300_link_finger_2_visual'>
          <pose frame=''>0 0 0 0 -0 0</pose>
          <geometry>
            <mesh>
              <scale>1 1 1</scale>
              <uri>/home/xkx/JCAR_V1_ws/src/kinova_description/meshes/finger_proximal.dae</uri>
            </mesh>
          </geometry>
        </visual>
        <visual name='j2s7s300_link_finger_2_fixed_joint_lump__j2s7s300_link_finger_tip_2_visual_1'>
          <pose frame=''>0.044 -0.003 0 0 -0 0</pose>
          <geometry>
            <mesh>
              <scale>1 1 1</scale>
              <uri>/home/xkx/JCAR_V1_ws/src/kinova_description/meshes/finger_distal.dae</uri>
            </mesh>
          </geometry>
        </visual>
        <self_collide>0</self_collide>
        <kinematic>0</kinematic>
      </link>
      <joint name='j2s7s300_joint_finger_2' type='revolute'>
        <child>j2s7s300_link_finger_2</child>
        <parent>j2s7s300_link_7</parent>
        <axis>
          <xyz>-0.865151 0.501511 0</xyz>
          <limit>
            <lower>0</lower>
            <upper>2</upper>
            <effort>2000</effort>
            <velocity>1</velocity>
          </limit>
          <dynamics>
            <spring_reference>0</spring_reference>
            <spring_stiffness>0</spring_stiffness>
          </dynamics>
          <use_parent_model_frame>1</use_parent_model_frame>
        </axis>
      </joint>
      <link name='j2s7s300_link_finger_3'>
        <pose frame=''>0.455314 0.11209 0.741556 -1.5708 0.649262 0.67614</pose>
        <inertial>
          <pose frame=''>0.044 -0.0015 0 0 -0 0</pose>
          <mass>0.02</mass>
          <inertia>
            <ixx>1.62499e-06</ixx>
            <ixy>6.6e-07</ixy>
            <ixz>0</ixz>
            <iyy>1.126e-05</iyy>
            <iyz>0</iyz>
            <izz>9.885e-06</izz>
          </inertia>
        </inertial>
        <collision name='j2s7s300_link_finger_3_collision'>
          <pose frame=''>0 0 0 0 -0 0</pose>
          <geometry>
            <mesh>
              <scale>1 1 1</scale>
              <uri>/home/xkx/JCAR_V1_ws/src/kinova_description/meshes/finger_proximal.dae</uri>
            </mesh>
          </geometry>
          <max_contacts>10</max_contacts>
          <surface>
            <contact>
              <ode/>
            </contact>
            <bounce/>
            <friction>
              <torsional>
                <ode/>
              </torsional>
              <ode/>
            </friction>
          </surface>
        </collision>
        <collision name='j2s7s300_link_finger_3_fixed_joint_lump__j2s7s300_link_finger_tip_3_collision_1'>
          <pose frame=''>0.044 -0.003 0 0 -0 0</pose>
          <geometry>
            <mesh>
              <scale>1 1 1</scale>
              <uri>/home/xkx/JCAR_V1_ws/src/kinova_description/meshes/finger_distal.dae</uri>
            </mesh>
          </geometry>
          <max_contacts>10</max_contacts>
          <surface>
            <contact>
              <ode/>
            </contact>
            <bounce/>
            <friction>
              <torsional>
                <ode/>
              </torsional>
              <ode/>
            </friction>
          </surface>
        </collision>
        <visual name='j2s7s300_link_finger_3_visual'>
          <pose frame=''>0 0 0 0 -0 0</pose>
          <geometry>
            <mesh>
              <scale>1 1 1</scale>
              <uri>/home/xkx/JCAR_V1_ws/src/kinova_description/meshes/finger_proximal.dae</uri>
            </mesh>
          </geometry>
        </visual>
        <visual name='j2s7s300_link_finger_3_fixed_joint_lump__j2s7s300_link_finger_tip_3_visual_1'>
          <pose frame=''>0.044 -0.003 0 0 -0 0</pose>
          <geometry>
            <mesh>
              <scale>1 1 1</scale>
              <uri>/home/xkx/JCAR_V1_ws/src/kinova_description/meshes/finger_distal.dae</uri>
            </mesh>
          </geometry>
        </visual>
        <self_collide>0</self_collide>
        <kinematic>0</kinematic>
      </link>
      <joint name='j2s7s300_joint_finger_3' type='revolute'>
        <child>j2s7s300_link_finger_3</child>
        <parent>j2s7s300_link_7</parent>
        <axis>
          <xyz>-0.625787 0.779994 0</xyz>
          <limit>
            <lower>0</lower>
            <upper>2</upper>
            <effort>2000</effort>
            <velocity>1</velocity>
          </limit>
          <dynamics>
            <spring_reference>0</spring_reference>
            <spring_stiffness>0</spring_stiffness>
          </dynamics>
          <use_parent_model_frame>1</use_parent_model_frame>
        </axis>
      </joint>
      <static>0</static>
      <plugin name='gazebo_ros_control' filename='libgazebo_ros_control.so'>
        <robotNamespace>j2s7s300</robotNamespace>
        <robotSimType>gazebo_ros_control/DefaultRobotHWSim</robotSimType>
      </plugin>
      <pose frame=''>0 0 0 0 -0 0</pose>
    </model>
    <state world_name='default'>
      <sim_time>42 571000000</sim_time>
      <real_time>43 396716566</real_time>
      <wall_time>1527986443 982768068</wall_time>
      <iterations>42571</iterations>
      <model name='ground_plane'>
        <pose frame=''>0 0 0 0 -0 0</pose>
        <scale>1 1 1</scale>
        <link name='link'>
          <pose frame=''>0 0 0 0 -0 0</pose>
          <velocity>0 0 0 0 -0 0</velocity>
          <acceleration>0 0 0 0 -0 0</acceleration>
          <wrench>0 0 0 0 -0 0</wrench>
        </link>
      </model>
      <model name='kinect'>
        <pose frame=''>0.098166 -0.20872 1.29518 1.36296 1.57079 2.93375</pose>
        <scale>1 1 1</scale>
        <link name='link'>
          <pose frame=''>0.098166 -0.20872 1.29518 1.36296 1.57079 2.93375</pose>
          <velocity>0 0 0 0 -0 0</velocity>
          <acceleration>0 0 0 0 -0 0</acceleration>
          <wrench>0 0 0 0 -0 0</wrench>
        </link>
      </model>
      <model name='robot_on_table'>
        <pose frame=''>0 0 0 0 -0 0</pose>
        <scale>1 1 1</scale>
        <link name='j2s7s300_link_1'>
          <pose frame=''>0.414405 0.098646 0.940327 3.14158 -4.1e-05 1.06603</pose>
          <velocity>-1.5e-05 -1.7e-05 -0 -8e-05 6.9e-05 0.017731</velocity>
          <acceleration>-0.001662 -0.002648 -0.000166 -0.761901 -0.804605 1.51283</acceleration>
          <wrench>-0.001243 -0.00198 -0.000124 0 -0 0</wrench>
        </link>
        <link name='j2s7s300_link_2'>
          <pose frame=''>0.415808 0.097876 1.05908 -1.57079 -0.767637 1.06604</pose>
          <velocity>-3e-06 8e-06 -0 0.001151 -0.000653 0.017701</velocity>
          <acceleration>0.049066 -0.032774 -0.003033 0.650747 0.480065 2.5032</acceleration>
          <wrench>0.041446 -0.027684 -0.002562 0 -0 0</wrench>
        </link>
        <link name='j2s7s300_link_3'>
          <pose frame=''>0.346968 -0.026726 1.20659 2.98903 0.755385 -2.29619</pose>
          <velocity>0.002109 -0.001383 -0.000181 0.019266 0.032254 -0.021186</velocity>
          <acceleration>0.146887 -0.096191 -0.009012 1.17403 -0.514831 1.82449</acceleration>
          <wrench>0.124075 -0.081253 -0.007613 0 -0 0</wrench>
        </link>
        <link name='j2s7s300_link_4'>
          <pose frame=''>0.27812 -0.151342 1.3541 -1.44826 0.440111 1.00241</pose>
          <velocity>0.004289 -0.002686 -0.000305 0.018622 0.032736 -0.020968</velocity>
          <acceleration>0.058714 -0.039694 -0.008002 2.02802 -0.763544 -0.444308</acceleration>
          <wrench>0.039708 -0.026845 -0.005412 0 -0 0</wrench>
        </link>
        <link name='j2s7s300_link_5'>
          <pose frame=''>0.2188 -0.218224 1.16672 -0.412355 0.200609 -0.421824</pose>
          <velocity>-0.003287 0.002058 0.000314 0.005944 0.020972 -0.056667</velocity>
          <acceleration>-0.229453 0.180135 0.021403 2.24199 1.04722 -0.847666</acceleration>
          <wrench>-0.106237 0.083402 0.009909 0 -0 0</wrench>
        </link>
        <link name='j2s7s300_link_6'>
          <pose frame=''>0.184496 -0.24841 1.07358 -2.24926 0.894408 -0.896074</pose>
          <velocity>-0.006969 0.004558 0.000846 0.026329 0.079109 -0.083026</velocity>
          <acceleration>-0.384279 0.454065 0.176532 -1.80344 1.50704 2.76436</acceleration>
          <wrench>-0.177921 0.210232 0.081734 0 -0 0</wrench>
        </link>
        <link name='j2s7s300_link_7'>
          <pose frame=''>0.094303 -0.239895 1.02302 1.01886 -0.377666 1.69992</pose>
          <velocity>-0.010278 0.013381 0.008213 0.025767 0.079309 -0.083364</velocity>
          <acceleration>-0.518451 0.926613 0.510821 0.365921 0.105233 -2.90595</acceleration>
          <wrench>-0.376914 0.673647 0.371367 0 -0 0</wrench>
        </link>
        <link name='j2s7s300_link_finger_1'>
          <pose frame=''>-0.020706 -0.239747 0.9929 -1.79725 0.519916 3.04449</pose>
          <velocity>-0.012659 0.023753 0.017341 0.025387 0.120506 -0.075126</velocity>
          <acceleration>-0.824319 1.3409 1.27187 -0.979436 1.11669 2.28586</acceleration>
          <wrench>-0.016486 0.026818 0.025437 0 -0 0</wrench>
        </link>
        <link name='j2s7s300_link_finger_2'>
          <pose frame=''>0.004806 -0.199691 0.953839 0.475004 0.963022 2.37156</pose>
          <velocity>-0.01242 0.022632 0.016353 0.011665 0.136873 -0.048347</velocity>
          <acceleration>-1.62026 0.716907 0.958311 -0.753087 -1.55271 1.43691</acceleration>
          <wrench>-0.032405 0.014338 0.019166 0 -0 0</wrench>
        </link>
        <link name='j2s7s300_link_finger_3'>
          <pose frame=''>0.010134 -0.240726 0.937421 1.21309 0.901312 2.88687</pose>
          <velocity>-0.017145 0.022608 0.014868 0.024361 0.131218 -0.071718</velocity>
          <acceleration>-1.48383 1.05325 1.15286 -1.05729 0.57723 1.58533</acceleration>
          <wrench>-0.029677 0.021065 0.023057 0 -0 0</wrench>
        </link>
        <link name='table_base'>
          <pose frame=''>0 0 0.273 0 -0 0</pose>
          <velocity>0 0 0 0 -0 0</velocity>
          <acceleration>0 0 -0 0 -0 0</acceleration>
          <wrench>0.000124 0.000123 -9.8e-05 0 -0 0</wrench>
        </link>
      </model>
      <light name='sun'>
        <pose frame=''>0 0 10 0 -0 0</pose>
      </light>
    </state>
    <gui fullscreen='0'>
      <camera name='user_camera'>
        <pose frame=''>1.46286 -3.55914 3.15712 -0 0.383642 1.7602</pose>
        <view_controller>orbit</view_controller>
        <projection_type>perspective</projection_type>
      </camera>
    </gui>
  </world>
</sdf>
