<sdf version='1.6'>
  <world name='default'>
    <light name='sun' type='directional'>
      <cast_shadows>1</cast_shadows>
      <pose frame=''>0 0 10 0 -0 0</pose>
      <diffuse>0.8 0.8 0.8 1</diffuse>
      <specular>0.2 0.2 0.2 1</specular>
      <attenuation>
        <range>1000</range>
        <constant>0.9</constant>
        <linear>0.01</linear>
        <quadratic>0.001</quadratic>
      </attenuation>
      <direction>-0.5 0.1 -0.9</direction>
    </light>
    <model name='ground_plane'>
      <static>1</static>
      <link name='link'>
        <collision name='collision'>
          <geometry>
            <plane>
              <normal>0 0 1</normal>
              <size>100 100</size>
            </plane>
          </geometry>
          <surface>
            <friction>
              <ode>
                <mu>100</mu>
                <mu2>50</mu2>
              </ode>
              <torsional>
                <ode/>
              </torsional>
            </friction>
            <contact>
              <ode/>
            </contact>
            <bounce/>
          </surface>
          <max_contacts>10</max_contacts>
        </collision>
        <visual name='visual'>
          <cast_shadows>0</cast_shadows>
          <geometry>
            <plane>
              <normal>0 0 1</normal>
              <size>100 100</size>
            </plane>
          </geometry>
          <material>
            <script>
              <uri>file://media/materials/scripts/gazebo.material</uri>
              <name>Gazebo/Grey</name>
            </script>
          </material>
        </visual>
        <self_collide>0</self_collide>
        <kinematic>0</kinematic>
      </link>
    </model>
    <gravity>0 0 -9.8</gravity>
    <magnetic_field>6e-06 2.3e-05 -4.2e-05</magnetic_field>
    <atmosphere type='adiabatic'/>
    <physics name='default_physics' default='0' type='ode'>
      <max_step_size>0.001</max_step_size>
      <real_time_factor>1</real_time_factor>
      <real_time_update_rate>1000</real_time_update_rate>
    </physics>
    <scene>
      <ambient>0.4 0.4 0.4 1</ambient>
      <background>0.7 0.7 0.7 1</background>
      <shadows>1</shadows>
    </scene>
    <spherical_coordinates>
      <surface_model>EARTH_WGS84</surface_model>
      <latitude_deg>0</latitude_deg>
      <longitude_deg>0</longitude_deg>
      <elevation>0</elevation>
      <heading_deg>0</heading_deg>
    </spherical_coordinates>
    <model name='object_on_table'>
      <link name='table_base'>
        <pose frame=''>0 0 0.273 0 -0 0</pose>
        <inertial>
          <pose frame=''>0.018512 -0.047982 0.652828 0 -0 0</pose>
          <mass>4.03703e+06</mass>
          <inertia>
            <ixx>966458</ixx>
            <ixy>0.00707943</ixy>
            <ixz>-0.0112217</ixz>
            <iyy>1.0825e+06</iyy>
            <iyz>-270361</iyz>
            <izz>806693</izz>
          </inertia>
        </inertial>
        <collision name='table_base_collision'>
          <pose frame=''>0 0 0 0 -0 0</pose>
          <geometry>
            <mesh>
              <scale>1 1 1</scale>
              <uri>/home/xkx/JCAR_V1_ws/src/robot_grasp/models/table/meshes/table_base.STL</uri>
            </mesh>
          </geometry>
          <surface>
            <contact>
              <ode/>
            </contact>
            <friction>
              <ode/>
              <torsional>
                <ode/>
              </torsional>
            </friction>
            <bounce/>
          </surface>
          <max_contacts>10</max_contacts>
        </collision>
        <collision name='table_base_fixed_joint_lump__table_top_collision_1'>
          <pose frame=''>0.018512 0.221508 0.435076 1.5708 -0 0</pose>
          <geometry>
            <box>
              <size>1.05 0.015 0.005</size>
            </box>
          </geometry>
          <surface>
            <contact>
              <ode/>
            </contact>
            <friction>
              <ode/>
              <torsional>
                <ode/>
              </torsional>
            </friction>
            <bounce/>
          </surface>
          <max_contacts>10</max_contacts>
        </collision>
        <collision name='table_base_fixed_joint_lump__table_top_collision_2'>
          <pose frame=''>0.541012 -0.175992 0.435076 1.5708 -0 0</pose>
          <geometry>
            <box>
              <size>0.005 0.015 0.8</size>
            </box>
          </geometry>
          <surface>
            <contact>
              <ode/>
            </contact>
            <friction>
              <ode/>
              <torsional>
                <ode/>
              </torsional>
            </friction>
            <bounce/>
          </surface>
          <max_contacts>10</max_contacts>
        </collision>
        <collision name='table_base_fixed_joint_lump__table_top_collision_3'>
          <pose frame=''>0.018512 -0.175992 0.397576 1.5708 -0 0</pose>
          <geometry>
            <mesh>
              <scale>1 1 1</scale>
              <uri>/home/xkx/JCAR_V1_ws/src/robot_grasp/models/table/meshes/table_top.STL</uri>
            </mesh>
          </geometry>
          <surface>
            <contact>
              <ode/>
            </contact>
            <friction>
              <ode/>
              <torsional>
                <ode/>
              </torsional>
            </friction>
            <bounce/>
          </surface>
          <max_contacts>10</max_contacts>
        </collision>
        <collision name='table_base_fixed_joint_lump__basket_collision_4'>
          <pose frame=''>0.268512 -0.225992 0.457576 1.5708 -0 0</pose>
          <geometry>
            <mesh>
              <scale>0.001 0.001 0.001</scale>
              <uri>/home/xkx/JCAR_V1_ws/src/robot_grasp/models/grasp_object/basket.dae</uri>
            </mesh>
          </geometry>
          <surface>
            <contact>
              <ode/>
            </contact>
            <friction>
              <ode/>
              <torsional>
                <ode/>
              </torsional>
            </friction>
            <bounce/>
          </surface>
          <max_contacts>10</max_contacts>
        </collision>
        <collision name='table_base_fixed_joint_lump__basket2_collision_5'>
          <pose frame=''>-0.181488 -0.225992 0.457576 1.5708 -0 0</pose>
          <geometry>
            <mesh>
              <scale>0.001 0.001 0.001</scale>
              <uri>/home/xkx/JCAR_V1_ws/src/robot_grasp/models/grasp_object/basket.dae</uri>
            </mesh>
          </geometry>
          <surface>
            <contact>
              <ode/>
            </contact>
            <friction>
              <ode/>
              <torsional>
                <ode/>
              </torsional>
            </friction>
            <bounce/>
          </surface>
          <max_contacts>10</max_contacts>
        </collision>
        <collision name='table_base_fixed_joint_lump__kinect_support_collision_6'>
          <pose frame=''>0.118512 -0.475992 0.587576 1.5708 0 -1.5708</pose>
          <geometry>
            <mesh>
              <scale>0.001 0.001 0.001</scale>
              <uri>/home/xkx/JCAR_V1_ws/src/robot_grasp/models/grasp_object/meshes/kinect_support.dae</uri>
            </mesh>
          </geometry>
          <surface>
            <contact>
              <ode/>
            </contact>
            <friction>
              <ode/>
              <torsional>
                <ode/>
              </torsional>
            </friction>
            <bounce/>
          </surface>
          <max_contacts>10</max_contacts>
        </collision>
        <collision name='table_base_fixed_joint_lump__camera_link_collision_7'>
          <pose frame=''>0.118512 -0.210992 1.03358 -3.13396 1.57079 -1.56316</pose>
          <geometry>
            <box>
              <size>0.036 0.18 0.04</size>
            </box>
          </geometry>
          <max_contacts>10</max_contacts>
          <surface>
            <contact>
              <ode/>
            </contact>
            <bounce/>
            <friction>
              <torsional>
                <ode/>
              </torsional>
              <ode/>
            </friction>
          </surface>
        </collision>
        <visual name='table_base_visual'>
          <pose frame=''>0 0 0 0 -0 0</pose>
          <geometry>
            <mesh>
              <scale>1 1 1</scale>
              <uri>/home/xkx/JCAR_V1_ws/src/robot_grasp/models/table/meshes/table_base.STL</uri>
            </mesh>
          </geometry>
          <material>
            <script>
              <name>Gazebo/FlatBlack</name>
              <uri>file://media/materials/scripts/gazebo.material</uri>
            </script>
          </material>
        </visual>
        <visual name='table_base_fixed_joint_lump__table_top_visual_1'>
          <pose frame=''>0.018512 -0.175992 0.397576 1.5708 -0 0</pose>
          <geometry>
            <mesh>
              <scale>1 1 1</scale>
              <uri>/home/xkx/JCAR_V1_ws/src/robot_grasp/models/table/meshes/table_top.STL</uri>
            </mesh>
          </geometry>
          <material>
            <script>
              <name>Gazebo/White</name>
              <uri>file://media/materials/scripts/gazebo.material</uri>
            </script>
          </material>
        </visual>
        <visual name='table_base_fixed_joint_lump__table_top_visual_2'>
          <pose frame=''>0.018512 0.221508 0.435076 1.5708 -0 0</pose>
          <geometry>
            <box>
              <size>1.05 0.015 0.005</size>
            </box>
          </geometry>
          <material>
            <script>
              <name>Gazebo/White</name>
              <uri>file://media/materials/scripts/gazebo.material</uri>
            </script>
          </material>
        </visual>
        <visual name='table_base_fixed_joint_lump__table_top_visual_3'>
          <pose frame=''>0.541012 -0.175992 0.435076 1.5708 -0 0</pose>
          <geometry>
            <box>
              <size>0.005 0.015 0.8</size>
            </box>
          </geometry>
          <material>
            <script>
              <name>Gazebo/White</name>
              <uri>file://media/materials/scripts/gazebo.material</uri>
            </script>
          </material>
        </visual>
        <visual name='table_base_fixed_joint_lump__basket_visual_4'>
          <pose frame=''>0.268512 -0.225992 0.457576 1.5708 -0 0</pose>
          <geometry>
            <mesh>
              <scale>0.001 0.001 0.001</scale>
              <uri>/home/xkx/JCAR_V1_ws/src/robot_grasp/models/grasp_object/basket.dae</uri>
            </mesh>
          </geometry>
          <material>
            <script>
              <name>Gazebo/Green</name>
              <uri>file://media/materials/scripts/gazebo.material</uri>
            </script>
          </material>
        </visual>
        <visual name='table_base_fixed_joint_lump__basket2_visual_5'>
          <pose frame=''>-0.181488 -0.225992 0.457576 1.5708 -0 0</pose>
          <geometry>
            <mesh>
              <scale>0.001 0.001 0.001</scale>
              <uri>/home/xkx/JCAR_V1_ws/src/robot_grasp/models/grasp_object/basket.dae</uri>
            </mesh>
          </geometry>
          <material>
            <script>
              <name>Gazebo/Blue</name>
              <uri>file://media/materials/scripts/gazebo.material</uri>
            </script>
          </material>
        </visual>
        <visual name='table_base_fixed_joint_lump__kinect_support_visual_6'>
          <pose frame=''>0.118512 -0.475992 0.587576 1.5708 0 -1.5708</pose>
          <geometry>
            <mesh>
              <scale>0.001 0.001 0.001</scale>
              <uri>/home/xkx/JCAR_V1_ws/src/robot_grasp/models/table/meshes/kinect_support.dae</uri>
            </mesh>
          </geometry>
          <material>
            <script>
              <name>Gazebo/Black</name>
              <uri>file://media/materials/scripts/gazebo.material</uri>
            </script>
          </material>
        </visual>
        <visual name='table_base_fixed_joint_lump__camera_link_visual_7'>
          <pose frame=''>0.118512 -0.210992 1.01758 -3.13396 1.57079 -1.56316</pose>
          <geometry>
            <mesh>
              <scale>1 1 1</scale>
              <uri>/home/xkx/JCAR_V1_ws/src/robot_grasp/models/kinect/meshes/kinect.dae</uri>
            </mesh>
          </geometry>
        </visual>
        <velocity_decay/>
        <velocity_decay/>
        <velocity_decay/>
        <velocity_decay/>
        <velocity_decay/>
        <gravity>1</gravity>
        <velocity_decay/>
        <sensor name='camera' type='depth'>
          <always_on>1</always_on>
          <visualize>0</visualize>
          <update_rate>15</update_rate>
          <camera name='front'>
            <horizontal_fov>1.0472</horizontal_fov>
            <image>
              <format>B8G8R8</format>
              <width>1920</width>
              <height>1080</height>
            </image>
            <clip>
              <near>0.01</near>
              <far>9</far>
            </clip>
          </camera>
          <plugin name='camera_controller' filename='libgazebo_ros_openni_kinect.so'>
            <baseline>0.1</baseline>
            <alwaysOn>true</alwaysOn>
            <updateRate>15.0</updateRate>
            <cameraName>camera</cameraName>
            <imageTopicName>/camera/rgb/image_raw</imageTopicName>
            <cameraInfoTopicName>/camera/rgb/camera_info</cameraInfoTopicName>
            <depthImageTopicName>/camera/depth_registered/image_raw</depthImageTopicName>
            <depthImageCameraInfoTopicName>/camera/depth_registered/camera_info</depthImageCameraInfoTopicName>
            <pointCloudTopicName>/camera/depth_registered/points</pointCloudTopicName>
            <frameName>camera_rgb_optical_frame</frameName>
            <pointCloudCutoff>0.35</pointCloudCutoff>
            <pointCloudCutoffMax>4.5</pointCloudCutoffMax>
            <CxPrime>0</CxPrime>
            <Cx>900</Cx>
            <Cy>540</Cy>
            <focalLength>1.0</focalLength>
            <hackBaseline>0</hackBaseline>
            <robotNamespace>/</robotNamespace>
          </plugin>
          <pose frame=''>0.096512 -0.210992 1.01758 -3.13396 1.57079 -1.56316</pose>
        </sensor>
        <self_collide>0</self_collide>
        <kinematic>0</kinematic>
      </link>
      <joint name='j0' type='fixed'>
        <child>table_base</child>
        <parent>world</parent>
      </joint>
      <link name='table_base2'>
        <pose frame=''>0 0.85 0.273 0 -0 0</pose>
        <inertial>
          <pose frame=''>0.018512 -0.047982 0.652828 0 -0 0</pose>
          <mass>4.03703e+06</mass>
          <inertia>
            <ixx>966458</ixx>
            <ixy>-3.72871e-07</ixy>
            <ixz>-2.51261e-07</ixz>
            <iyy>1.0825e+06</iyy>
            <iyz>-270361</iyz>
            <izz>806693</izz>
          </inertia>
        </inertial>
        <collision name='table_base2_collision'>
          <pose frame=''>0 0 0 0 -0 0</pose>
          <geometry>
            <mesh>
              <scale>1 1 1</scale>
              <uri>/home/xkx/JCAR_V1_ws/src/robot_grasp/models/table/meshes/table_base.STL</uri>
            </mesh>
          </geometry>
          <surface>
            <contact>
              <ode/>
            </contact>
            <friction>
              <ode/>
              <torsional>
                <ode/>
              </torsional>
            </friction>
            <bounce/>
          </surface>
          <max_contacts>10</max_contacts>
        </collision>
        <collision name='table_base2_fixed_joint_lump__table_top2_collision_1'>
          <pose frame=''>0.018512 0.221508 0.435076 1.5708 -0 0</pose>
          <geometry>
            <box>
              <size>1.05 0.015 0.005</size>
            </box>
          </geometry>
          <surface>
            <contact>
              <ode/>
            </contact>
            <friction>
              <ode/>
              <torsional>
                <ode/>
              </torsional>
            </friction>
            <bounce/>
          </surface>
          <max_contacts>10</max_contacts>
        </collision>
        <collision name='table_base2_fixed_joint_lump__table_top2_collision_2'>
          <pose frame=''>0.541012 -0.175992 0.435076 1.5708 -0 0</pose>
          <geometry>
            <box>
              <size>0.005 0.015 0.8</size>
            </box>
          </geometry>
          <surface>
            <contact>
              <ode/>
            </contact>
            <friction>
              <ode/>
              <torsional>
                <ode/>
              </torsional>
            </friction>
            <bounce/>
          </surface>
          <max_contacts>10</max_contacts>
        </collision>
        <collision name='table_base2_fixed_joint_lump__table_top2_collision_3'>
          <pose frame=''>0.018512 -0.175992 0.397576 1.5708 -0 0</pose>
          <geometry>
            <mesh>
              <scale>1 1 1</scale>
              <uri>/home/xkx/JCAR_V1_ws/src/robot_grasp/models/table/meshes/table_top.STL</uri>
            </mesh>
          </geometry>
          <surface>
            <contact>
              <ode/>
            </contact>
            <friction>
              <ode/>
              <torsional>
                <ode/>
              </torsional>
            </friction>
            <bounce/>
          </surface>
          <max_contacts>10</max_contacts>
        </collision>
        <collision name='table_base2_fixed_joint_lump__arm_stand_collision_4'>
          <pose frame=''>0.018512 -0.510992 0.430576 1.5708 -0 -3.14159</pose>
          <geometry>
            <mesh>
              <scale>1 1 1</scale>
              <uri>/home/xkx/JCAR_V1_ws/src/robot_grasp/models/table/meshes/arm_stand.STL</uri>
            </mesh>
          </geometry>
          <surface>
            <contact>
              <ode/>
            </contact>
            <friction>
              <ode/>
              <torsional>
                <ode/>
              </torsional>
            </friction>
            <bounce/>
          </surface>
          <max_contacts>10</max_contacts>
        </collision>
        <collision name='table_base2_fixed_joint_lump__root_collision_5'>
          <pose frame=''>0.018512 -0.510992 0.510576 0 -0 -3.09159</pose>
          <geometry>
            <box>
              <size>1e-05 1e-05 1e-05</size>
            </box>
          </geometry>
          <max_contacts>10</max_contacts>
          <surface>
            <contact>
              <ode/>
            </contact>
            <bounce/>
            <friction>
              <torsional>
                <ode/>
              </torsional>
              <ode/>
            </friction>
          </surface>
        </collision>
        <collision name='table_base2_fixed_joint_lump__j2s7s300_link_base_collision_6'>
          <pose frame=''>0.018512 -0.510992 0.510576 0 -0 -3.09159</pose>
          <geometry>
            <mesh>
              <scale>1 1 1</scale>
              <uri>/home/xkx/JCAR_V1_ws/src/kinova_description/meshes/base.dae</uri>
            </mesh>
          </geometry>
          <max_contacts>10</max_contacts>
          <surface>
            <contact>
              <ode/>
            </contact>
            <bounce/>
            <friction>
              <torsional>
                <ode/>
              </torsional>
              <ode/>
            </friction>
          </surface>
        </collision>
        <visual name='table_base2_visual'>
          <pose frame=''>0 0 0 0 -0 0</pose>
          <geometry>
            <mesh>
              <scale>1 1 1</scale>
              <uri>/home/xkx/JCAR_V1_ws/src/robot_grasp/models/table/meshes/table_base.STL</uri>
            </mesh>
          </geometry>
          <material>
            <script>
              <name>Gazebo/FlatBlack</name>
              <uri>file://media/materials/scripts/gazebo.material</uri>
            </script>
          </material>
        </visual>
        <visual name='table_base2_fixed_joint_lump__table_top2_visual_1'>
          <pose frame=''>0.018512 -0.175992 0.397576 1.5708 -0 0</pose>
          <geometry>
            <mesh>
              <scale>1 1 1</scale>
              <uri>/home/xkx/JCAR_V1_ws/src/robot_grasp/models/table/meshes/table_top.STL</uri>
            </mesh>
          </geometry>
          <material>
            <script>
              <name>Gazebo/White</name>
              <uri>file://media/materials/scripts/gazebo.material</uri>
            </script>
          </material>
        </visual>
        <visual name='table_base2_fixed_joint_lump__table_top2_visual_2'>
          <pose frame=''>0.018512 0.221508 0.435076 1.5708 -0 0</pose>
          <geometry>
            <box>
              <size>1.05 0.015 0.005</size>
            </box>
          </geometry>
          <material>
            <script>
              <name>Gazebo/White</name>
              <uri>file://media/materials/scripts/gazebo.material</uri>
            </script>
          </material>
        </visual>
        <visual name='table_base2_fixed_joint_lump__table_top2_visual_3'>
          <pose frame=''>0.541012 -0.175992 0.435076 1.5708 -0 0</pose>
          <geometry>
            <box>
              <size>0.005 0.015 0.8</size>
            </box>
          </geometry>
          <material>
            <script>
              <name>Gazebo/White</name>
              <uri>file://media/materials/scripts/gazebo.material</uri>
            </script>
          </material>
        </visual>
        <visual name='table_base2_fixed_joint_lump__arm_stand_visual_4'>
          <pose frame=''>0.018512 -0.510992 0.430576 1.5708 -0 -3.14159</pose>
          <geometry>
            <mesh>
              <scale>1 1 1</scale>
              <uri>/home/xkx/JCAR_V1_ws/src/robot_grasp/models/table/meshes/arm_stand.STL</uri>
            </mesh>
          </geometry>
          <material>
            <script>
              <name>Gazebo/FlatBlack</name>
              <uri>file://media/materials/scripts/gazebo.material</uri>
            </script>
          </material>
        </visual>
        <visual name='table_base2_fixed_joint_lump__root_visual_5'>
          <pose frame=''>0.018512 -0.510992 0.510576 0 -0 -3.09159</pose>
          <geometry>
            <box>
              <size>1e-05 1e-05 1e-05</size>
            </box>
          </geometry>
        </visual>
        <visual name='table_base2_fixed_joint_lump__j2s7s300_link_base_visual_6'>
          <pose frame=''>0.018512 -0.510992 0.510576 0 -0 -3.09159</pose>
          <geometry>
            <mesh>
              <scale>1 1 1</scale>
              <uri>/home/xkx/JCAR_V1_ws/src/kinova_description/meshes/base.dae</uri>
            </mesh>
          </geometry>
        </visual>
        <velocity_decay/>
        <velocity_decay/>
        <gravity>1</gravity>
        <velocity_decay/>
        <self_collide>0</self_collide>
        <kinematic>0</kinematic>
      </link>
      <joint name='j02' type='fixed'>
        <child>table_base2</child>
        <parent>world</parent>
      </joint>
      <link name='j2s7s300_link_1'>
        <pose frame=''>0.018512 0.339008 0.940326 3.14159 -0 0.05</pose>
        <inertial>
          <pose frame=''>0 -0.002 -0.0605 0 -0 0</pose>
          <mass>0.7477</mass>
          <inertia>
            <ixx>0.00152032</ixx>
            <ixy>0</ixy>
            <ixz>0</ixz>
            <iyy>0.00152032</iyy>
            <iyz>0</iyz>
            <izz>0.00059816</izz>
          </inertia>
        </inertial>
        <collision name='j2s7s300_link_1_collision'>
          <pose frame=''>0 0 0 0 -0 0</pose>
          <geometry>
            <mesh>
              <scale>1 1 1</scale>
              <uri>/home/xkx/JCAR_V1_ws/src/kinova_description/meshes/shoulder.dae</uri>
            </mesh>
          </geometry>
          <max_contacts>10</max_contacts>
          <surface>
            <contact>
              <ode/>
            </contact>
            <bounce/>
            <friction>
              <torsional>
                <ode/>
              </torsional>
              <ode/>
            </friction>
          </surface>
        </collision>
        <visual name='j2s7s300_link_1_visual'>
          <pose frame=''>0 0 0 0 -0 0</pose>
          <geometry>
            <mesh>
              <scale>1 1 1</scale>
              <uri>/home/xkx/JCAR_V1_ws/src/kinova_description/meshes/shoulder.dae</uri>
            </mesh>
          </geometry>
        </visual>
        <visual name='j2s7s300_link_1_visual_1'>
          <pose frame=''>0 0 0 0 -0 0</pose>
          <geometry>
            <mesh>
              <scale>1 1 1</scale>
              <uri>/home/xkx/JCAR_V1_ws/src/kinova_description/meshes/ring_big.STL</uri>
            </mesh>
          </geometry>
        </visual>
        <self_collide>0</self_collide>
        <kinematic>0</kinematic>
      </link>
      <joint name='j2s7s300_joint_1' type='revolute'>
        <child>j2s7s300_link_1</child>
        <parent>table_base2</parent>
        <axis>
          <xyz>0 0 -1</xyz>
          <limit>
            <lower>-1e+16</lower>
            <upper>1e+16</upper>
          </limit>
          <dynamics>
            <damping>0</damping>
            <friction>0</friction>
            <spring_reference>0</spring_reference>
            <spring_stiffness>0</spring_stiffness>
          </dynamics>
          <use_parent_model_frame>1</use_parent_model_frame>
        </axis>
      </joint>
      <link name='j2s7s300_link_2'>
        <pose frame=''>0.018592 0.33741 1.05908 1.5708 -0 -3.09159</pose>
        <inertial>
          <pose frame=''>0 -0.103563 0 0 -0 0</pose>
          <mass>0.8447</mass>
          <inertia>
            <ixx>0.00247074</ixx>
            <ixy>0</ixy>
            <ixz>0</ixz>
            <iyy>0.000380115</iyy>
            <iyz>0</iyz>
            <izz>0.00247074</izz>
          </inertia>
        </inertial>
        <collision name='j2s7s300_link_2_collision'>
          <pose frame=''>0 0 0 0 -0 0</pose>
          <geometry>
            <mesh>
              <scale>1 1 1</scale>
              <uri>/home/xkx/JCAR_V1_ws/src/kinova_description/meshes/arm_half_1.dae</uri>
            </mesh>
          </geometry>
          <max_contacts>10</max_contacts>
          <surface>
            <contact>
              <ode/>
            </contact>
            <bounce/>
            <friction>
              <torsional>
                <ode/>
              </torsional>
              <ode/>
            </friction>
          </surface>
        </collision>
        <visual name='j2s7s300_link_2_visual'>
          <pose frame=''>0 0 0 0 -0 0</pose>
          <geometry>
            <mesh>
              <scale>1 1 1</scale>
              <uri>/home/xkx/JCAR_V1_ws/src/kinova_description/meshes/arm_half_1.dae</uri>
            </mesh>
          </geometry>
        </visual>
        <visual name='j2s7s300_link_2_visual_1'>
          <pose frame=''>0 0 0 0 -0 0</pose>
          <geometry>
            <mesh>
              <scale>1 1 1</scale>
              <uri>/home/xkx/JCAR_V1_ws/src/kinova_description/meshes/ring_big.STL</uri>
            </mesh>
          </geometry>
        </visual>
        <self_collide>0</self_collide>
        <kinematic>0</kinematic>
      </link>
      <joint name='j2s7s300_joint_2' type='revolute'>
        <child>j2s7s300_link_2</child>
        <parent>j2s7s300_link_1</parent>
        <axis>
          <xyz>-0.049979 0.99875 0</xyz>
          <limit>
            <lower>0.523599</lower>
            <upper>5.75959</upper>
            <effort>2000</effort>
            <velocity>1</velocity>
          </limit>
          <dynamics>
            <damping>0</damping>
            <friction>0</friction>
            <spring_reference>0</spring_reference>
            <spring_stiffness>0</spring_stiffness>
          </dynamics>
          <use_parent_model_frame>1</use_parent_model_frame>
        </axis>
      </joint>
      <link name='j2s7s300_link_3'>
        <pose frame=''>0.018592 0.33741 0.854076 0 0 -3.09159</pose>
        <inertial>
          <pose frame=''>0 0 -0.102245 0 -0 0</pose>
          <mass>0.8447</mass>
          <inertia>
            <ixx>0.00247074</ixx>
            <ixy>0</ixy>
            <ixz>0</ixz>
            <iyy>0.00247074</iyy>
            <iyz>0</iyz>
            <izz>0.000380115</izz>
          </inertia>
        </inertial>
        <collision name='j2s7s300_link_3_collision'>
          <pose frame=''>0 0 0 0 -0 0</pose>
          <geometry>
            <mesh>
              <scale>1 1 1</scale>
              <uri>/home/xkx/JCAR_V1_ws/src/kinova_description/meshes/arm_half_2.dae</uri>
            </mesh>
          </geometry>
          <max_contacts>10</max_contacts>
          <surface>
            <contact>
              <ode/>
            </contact>
            <bounce/>
            <friction>
              <torsional>
                <ode/>
              </torsional>
              <ode/>
            </friction>
          </surface>
        </collision>
        <visual name='j2s7s300_link_3_visual'>
          <pose frame=''>0 0 0 0 -0 0</pose>
          <geometry>
            <mesh>
              <scale>1 1 1</scale>
              <uri>/home/xkx/JCAR_V1_ws/src/kinova_description/meshes/arm_half_2.dae</uri>
            </mesh>
          </geometry>
        </visual>
        <visual name='j2s7s300_link_3_visual_1'>
          <pose frame=''>0 0 0 0 -0 0</pose>
          <geometry>
            <mesh>
              <scale>1 1 1</scale>
              <uri>/home/xkx/JCAR_V1_ws/src/kinova_description/meshes/ring_big.STL</uri>
            </mesh>
          </geometry>
        </visual>
        <self_collide>0</self_collide>
        <kinematic>0</kinematic>
      </link>
      <joint name='j2s7s300_joint_3' type='revolute'>
        <child>j2s7s300_link_3</child>
        <parent>j2s7s300_link_2</parent>
        <axis>
          <xyz>0 0 1</xyz>
          <limit>
            <lower>-1e+16</lower>
            <upper>1e+16</upper>
          </limit>
          <dynamics>
            <damping>0</damping>
            <friction>0</friction>
            <spring_reference>0</spring_reference>
            <spring_stiffness>0</spring_stiffness>
          </dynamics>
          <use_parent_model_frame>1</use_parent_model_frame>
        </axis>
      </joint>
      <link name='j2s7s300_link_4'>
        <pose frame=''>0.018592 0.33741 0.649076 1.5708 -0 0.05</pose>
        <inertial>
          <pose frame=''>0 0.081 -0.0086 0 -0 0</pose>
          <mass>0.6763</mass>
          <inertia>
            <ixx>0.00142022</ixx>
            <ixy>0</ixy>
            <ixz>0</ixz>
            <iyy>0.000304335</iyy>
            <iyz>0</iyz>
            <izz>0.00142022</izz>
          </inertia>
        </inertial>
        <collision name='j2s7s300_link_4_collision'>
          <pose frame=''>0 0 0 0 -0 0</pose>
          <geometry>
            <mesh>
              <scale>1 1 1</scale>
              <uri>/home/xkx/JCAR_V1_ws/src/kinova_description/meshes/forearm.dae</uri>
            </mesh>
          </geometry>
          <max_contacts>10</max_contacts>
          <surface>
            <contact>
              <ode/>
            </contact>
            <bounce/>
            <friction>
              <torsional>
                <ode/>
              </torsional>
              <ode/>
            </friction>
          </surface>
        </collision>
        <visual name='j2s7s300_link_4_visual'>
          <pose frame=''>0 0 0 0 -0 0</pose>
          <geometry>
            <mesh>
              <scale>1 1 1</scale>
              <uri>/home/xkx/JCAR_V1_ws/src/kinova_description/meshes/forearm.dae</uri>
            </mesh>
          </geometry>
        </visual>
        <visual name='j2s7s300_link_4_visual_1'>
          <pose frame=''>0 0 0 0 -0 0</pose>
          <geometry>
            <mesh>
              <scale>1 1 1</scale>
              <uri>/home/xkx/JCAR_V1_ws/src/kinova_description/meshes/ring_small.STL</uri>
            </mesh>
          </geometry>
        </visual>
        <self_collide>0</self_collide>
        <kinematic>0</kinematic>
      </link>
      <joint name='j2s7s300_joint_4' type='revolute'>
        <child>j2s7s300_link_4</child>
        <parent>j2s7s300_link_3</parent>
        <axis>
          <xyz>0.049979 -0.99875 0</xyz>
          <limit>
            <lower>0.523599</lower>
            <upper>5.75959</upper>
            <effort>2000</effort>
            <velocity>1</velocity>
          </limit>
          <dynamics>
            <damping>0</damping>
            <friction>0</friction>
            <spring_reference>0</spring_reference>
            <spring_stiffness>0</spring_stiffness>
          </dynamics>
          <use_parent_model_frame>1</use_parent_model_frame>
        </axis>
      </joint>
      <link name='j2s7s300_link_5'>
        <pose frame=''>0.018022 0.348796 0.856376 -3.14159 -0 -3.09159</pose>
        <inertial>
          <pose frame=''>0 0.002885 -0.054193 0 -0 0</pose>
          <mass>0.463</mass>
          <inertia>
            <ixx>0.000432132</ixx>
            <ixy>0</ixy>
            <ixz>0</ixz>
            <iyy>0.000432132</iyy>
            <iyz>0</iyz>
            <izz>9.26e-05</izz>
          </inertia>
        </inertial>
        <collision name='j2s7s300_link_5_collision'>
          <pose frame=''>0 0 0 0 -0 0</pose>
          <geometry>
            <mesh>
              <scale>1 1 1</scale>
              <uri>/home/xkx/JCAR_V1_ws/src/kinova_description/meshes/wrist_spherical_1.dae</uri>
            </mesh>
          </geometry>
          <max_contacts>10</max_contacts>
          <surface>
            <contact>
              <ode/>
            </contact>
            <bounce/>
            <friction>
              <torsional>
                <ode/>
              </torsional>
              <ode/>
            </friction>
          </surface>
        </collision>
        <visual name='j2s7s300_link_5_visual'>
          <pose frame=''>0 0 0 0 -0 0</pose>
          <geometry>
            <mesh>
              <scale>1 1 1</scale>
              <uri>/home/xkx/JCAR_V1_ws/src/kinova_description/meshes/wrist_spherical_1.dae</uri>
            </mesh>
          </geometry>
        </visual>
        <visual name='j2s7s300_link_5_visual_1'>
          <pose frame=''>0 0 0 0 -0 0</pose>
          <geometry>
            <mesh>
              <scale>1 1 1</scale>
              <uri>/home/xkx/JCAR_V1_ws/src/kinova_description/meshes/ring_small.STL</uri>
            </mesh>
          </geometry>
        </visual>
        <self_collide>0</self_collide>
        <kinematic>0</kinematic>
      </link>
      <joint name='j2s7s300_joint_5' type='revolute'>
        <child>j2s7s300_link_5</child>
        <parent>j2s7s300_link_4</parent>
        <axis>
          <xyz>0 0 -1</xyz>
          <limit>
            <lower>-1e+16</lower>
            <upper>1e+16</upper>
          </limit>
          <dynamics>
            <damping>0</damping>
            <friction>0</friction>
            <spring_reference>0</spring_reference>
            <spring_stiffness>0</spring_stiffness>
          </dynamics>
          <use_parent_model_frame>1</use_parent_model_frame>
        </axis>
      </joint>
      <link name='j2s7s300_link_6'>
        <pose frame=''>0.018022 0.348796 0.960126 -1.5708 -0 0.05</pose>
        <inertial>
          <pose frame=''>0 0.049721 -0.002856 0 -0 0</pose>
          <mass>0.463</mass>
          <inertia>
            <ixx>0.000432132</ixx>
            <ixy>0</ixy>
            <ixz>0</ixz>
            <iyy>9.26e-05</iyy>
            <iyz>0</iyz>
            <izz>0.000432132</izz>
          </inertia>
        </inertial>
        <collision name='j2s7s300_link_6_collision'>
          <pose frame=''>0 0 0 0 -0 0</pose>
          <geometry>
            <mesh>
              <scale>1 1 1</scale>
              <uri>/home/xkx/JCAR_V1_ws/src/kinova_description/meshes/wrist_spherical_2.dae</uri>
            </mesh>
          </geometry>
          <max_contacts>10</max_contacts>
          <surface>
            <contact>
              <ode/>
            </contact>
            <bounce/>
            <friction>
              <torsional>
                <ode/>
              </torsional>
              <ode/>
            </friction>
          </surface>
        </collision>
        <visual name='j2s7s300_link_6_visual'>
          <pose frame=''>0 0 0 0 -0 0</pose>
          <geometry>
            <mesh>
              <scale>1 1 1</scale>
              <uri>/home/xkx/JCAR_V1_ws/src/kinova_description/meshes/wrist_spherical_2.dae</uri>
            </mesh>
          </geometry>
        </visual>
        <visual name='j2s7s300_link_6_visual_1'>
          <pose frame=''>0 0 0 0 -0 0</pose>
          <geometry>
            <mesh>
              <scale>1 1 1</scale>
              <uri>/home/xkx/JCAR_V1_ws/src/kinova_description/meshes/ring_small.STL</uri>
            </mesh>
          </geometry>
        </visual>
        <self_collide>0</self_collide>
        <kinematic>0</kinematic>
      </link>
      <joint name='j2s7s300_joint_6' type='revolute'>
        <child>j2s7s300_link_6</child>
        <parent>j2s7s300_link_5</parent>
        <axis>
          <xyz>-0.049979 0.99875 0</xyz>
          <limit>
            <lower>0.523599</lower>
            <upper>5.75959</upper>
            <effort>2000</effort>
            <velocity>1</velocity>
          </limit>
          <dynamics>
            <damping>0</damping>
            <friction>0</friction>
            <spring_reference>0</spring_reference>
            <spring_stiffness>0</spring_stiffness>
          </dynamics>
          <use_parent_model_frame>1</use_parent_model_frame>
        </axis>
      </joint>
      <link name='j2s7s300_link_7'>
        <pose frame=''>0.018022 0.348796 0.856376 0 0 -3.09159</pose>
        <inertial>
          <pose frame=''>0 0 -0.06 0 -0 0</pose>
          <mass>0.727</mass>
          <inertia>
            <ixx>0.000345324</ixx>
            <ixy>0</ixy>
            <ixz>0</ixz>
            <iyy>0.000345324</iyy>
            <iyz>0</iyz>
            <izz>0.0005816</izz>
          </inertia>
        </inertial>
        <collision name='j2s7s300_link_7_collision'>
          <pose frame=''>0 0 0 0 -0 0</pose>
          <geometry>
            <mesh>
              <scale>1 1 1</scale>
              <uri>/home/xkx/JCAR_V1_ws/src/kinova_description/meshes/hand_3finger.dae</uri>
            </mesh>
          </geometry>
          <max_contacts>10</max_contacts>
          <surface>
            <contact>
              <ode/>
            </contact>
            <bounce/>
            <friction>
              <torsional>
                <ode/>
              </torsional>
              <ode/>
            </friction>
          </surface>
        </collision>
        <collision name='j2s7s300_link_7_fixed_joint_lump__j2s7s300_end_effector_collision_1'>
          <pose frame=''>0 0 -0.16 -3.14159 -0 0</pose>
          <geometry>
            <box>
              <size>1e-05 1e-05 1e-05</size>
            </box>
          </geometry>
          <max_contacts>10</max_contacts>
          <surface>
            <contact>
              <ode/>
            </contact>
            <bounce/>
            <friction>
              <torsional>
                <ode/>
              </torsional>
              <ode/>
            </friction>
          </surface>
        </collision>
        <visual name='j2s7s300_link_7_visual'>
          <pose frame=''>0 0 0 0 -0 0</pose>
          <geometry>
            <mesh>
              <scale>1 1 1</scale>
              <uri>/home/xkx/JCAR_V1_ws/src/kinova_description/meshes/hand_3finger.dae</uri>
            </mesh>
          </geometry>
        </visual>
        <visual name='j2s7s300_link_7_visual_1'>
          <pose frame=''>0 0 0 0 -0 0</pose>
          <geometry>
            <mesh>
              <scale>1 1 1</scale>
              <uri>/home/xkx/JCAR_V1_ws/src/kinova_description/meshes/ring_small.STL</uri>
            </mesh>
          </geometry>
        </visual>
        <visual name='j2s7s300_link_7_fixed_joint_lump__j2s7s300_end_effector_visual_2'>
          <pose frame=''>0 0 -0.16 -3.14159 -0 0</pose>
          <geometry>
            <box>
              <size>1e-05 1e-05 1e-05</size>
            </box>
          </geometry>
        </visual>
        <self_collide>0</self_collide>
        <kinematic>0</kinematic>
      </link>
      <joint name='j2s7s300_joint_7' type='revolute'>
        <child>j2s7s300_link_7</child>
        <parent>j2s7s300_link_6</parent>
        <axis>
          <xyz>0 0 1</xyz>
          <limit>
            <lower>-1e+16</lower>
            <upper>1e+16</upper>
          </limit>
          <dynamics>
            <damping>0</damping>
            <friction>0</friction>
            <spring_reference>0</spring_reference>
            <spring_stiffness>0</spring_stiffness>
          </dynamics>
          <use_parent_model_frame>1</use_parent_model_frame>
        </axis>
      </joint>
      <link name='j2s7s300_link_finger_1'>
        <pose frame=''>0.016798 0.317435 0.741706 -1.5708 0.649262 -1.73198</pose>
        <inertial>
          <pose frame=''>0.044 -0.0015 0 0 -0 0</pose>
          <mass>0.02</mass>
          <inertia>
            <ixx>1.62499e-06</ixx>
            <ixy>6.6e-07</ixy>
            <ixz>0</ixz>
            <iyy>1.126e-05</iyy>
            <iyz>0</iyz>
            <izz>9.885e-06</izz>
          </inertia>
        </inertial>
        <collision name='j2s7s300_link_finger_1_collision'>
          <pose frame=''>0 0 0 0 -0 0</pose>
          <geometry>
            <mesh>
              <scale>1 1 1</scale>
              <uri>/home/xkx/JCAR_V1_ws/src/kinova_description/meshes/finger_proximal.dae</uri>
            </mesh>
          </geometry>
          <max_contacts>10</max_contacts>
          <surface>
            <contact>
              <ode/>
            </contact>
            <bounce/>
            <friction>
              <torsional>
                <ode/>
              </torsional>
              <ode/>
            </friction>
          </surface>
        </collision>
        <collision name='j2s7s300_link_finger_1_fixed_joint_lump__j2s7s300_link_finger_tip_1_collision_1'>
          <pose frame=''>0.044 -0.003 0 0 -0 0</pose>
          <geometry>
            <mesh>
              <scale>1 1 1</scale>
              <uri>/home/xkx/JCAR_V1_ws/src/kinova_description/meshes/finger_distal.dae</uri>
            </mesh>
          </geometry>
          <max_contacts>10</max_contacts>
          <surface>
            <contact>
              <ode/>
            </contact>
            <bounce/>
            <friction>
              <torsional>
                <ode/>
              </torsional>
              <ode/>
            </friction>
          </surface>
        </collision>
        <visual name='j2s7s300_link_finger_1_visual'>
          <pose frame=''>0 0 0 0 -0 0</pose>
          <geometry>
            <mesh>
              <scale>1 1 1</scale>
              <uri>/home/xkx/JCAR_V1_ws/src/kinova_description/meshes/finger_proximal.dae</uri>
            </mesh>
          </geometry>
        </visual>
        <visual name='j2s7s300_link_finger_1_fixed_joint_lump__j2s7s300_link_finger_tip_1_visual_1'>
          <pose frame=''>0.044 -0.003 0 0 -0 0</pose>
          <geometry>
            <mesh>
              <scale>1 1 1</scale>
              <uri>/home/xkx/JCAR_V1_ws/src/kinova_description/meshes/finger_distal.dae</uri>
            </mesh>
          </geometry>
        </visual>
        <self_collide>0</self_collide>
        <kinematic>0</kinematic>
      </link>
      <joint name='j2s7s300_joint_finger_1' type='revolute'>
        <child>j2s7s300_link_finger_1</child>
        <parent>j2s7s300_link_7</parent>
        <axis>
          <xyz>0.987038 -0.160488 0</xyz>
          <limit>
            <lower>0</lower>
            <upper>2</upper>
            <effort>2000</effort>
            <velocity>1</velocity>
          </limit>
          <dynamics>
            <spring_reference>0</spring_reference>
            <spring_stiffness>0</spring_stiffness>
          </dynamics>
          <use_parent_model_frame>1</use_parent_model_frame>
        </axis>
      </joint>
      <link name='j2s7s300_link_finger_2'>
        <pose frame=''>-0.005563 0.374719 0.741556 -1.5708 0.649262 1.80545</pose>
        <inertial>
          <pose frame=''>0.044 -0.0015 0 0 -0 0</pose>
          <mass>0.02</mass>
          <inertia>
            <ixx>1.62499e-06</ixx>
            <ixy>6.6e-07</ixy>
            <ixz>0</ixz>
            <iyy>1.126e-05</iyy>
            <iyz>0</iyz>
            <izz>9.885e-06</izz>
          </inertia>
        </inertial>
        <collision name='j2s7s300_link_finger_2_collision'>
          <pose frame=''>0 0 0 0 -0 0</pose>
          <geometry>
            <mesh>
              <scale>1 1 1</scale>
              <uri>/home/xkx/JCAR_V1_ws/src/kinova_description/meshes/finger_proximal.dae</uri>
            </mesh>
          </geometry>
          <max_contacts>10</max_contacts>
          <surface>
            <contact>
              <ode/>
            </contact>
            <bounce/>
            <friction>
              <torsional>
                <ode/>
              </torsional>
              <ode/>
            </friction>
          </surface>
        </collision>
        <collision name='j2s7s300_link_finger_2_fixed_joint_lump__j2s7s300_link_finger_tip_2_collision_1'>
          <pose frame=''>0.044 -0.003 0 0 -0 0</pose>
          <geometry>
            <mesh>
              <scale>1 1 1</scale>
              <uri>/home/xkx/JCAR_V1_ws/src/kinova_description/meshes/finger_distal.dae</uri>
            </mesh>
          </geometry>
          <max_contacts>10</max_contacts>
          <surface>
            <contact>
              <ode/>
            </contact>
            <bounce/>
            <friction>
              <torsional>
                <ode/>
              </torsional>
              <ode/>
            </friction>
          </surface>
        </collision>
        <visual name='j2s7s300_link_finger_2_visual'>
          <pose frame=''>0 0 0 0 -0 0</pose>
          <geometry>
            <mesh>
              <scale>1 1 1</scale>
              <uri>/home/xkx/JCAR_V1_ws/src/kinova_description/meshes/finger_proximal.dae</uri>
            </mesh>
          </geometry>
        </visual>
        <visual name='j2s7s300_link_finger_2_fixed_joint_lump__j2s7s300_link_finger_tip_2_visual_1'>
          <pose frame=''>0.044 -0.003 0 0 -0 0</pose>
          <geometry>
            <mesh>
              <scale>1 1 1</scale>
              <uri>/home/xkx/JCAR_V1_ws/src/kinova_description/meshes/finger_distal.dae</uri>
            </mesh>
          </geometry>
        </visual>
        <self_collide>0</self_collide>
        <kinematic>0</kinematic>
      </link>
      <joint name='j2s7s300_joint_finger_2' type='revolute'>
        <child>j2s7s300_link_finger_2</child>
        <parent>j2s7s300_link_7</parent>
        <axis>
          <xyz>-0.972594 -0.232508 0</xyz>
          <limit>
            <lower>0</lower>
            <upper>2</upper>
            <effort>2000</effort>
            <velocity>1</velocity>
          </limit>
          <dynamics>
            <spring_reference>0</spring_reference>
            <spring_stiffness>0</spring_stiffness>
          </dynamics>
          <use_parent_model_frame>1</use_parent_model_frame>
        </axis>
      </joint>
      <link name='j2s7s300_link_finger_3'>
        <pose frame=''>0.038901 0.376944 0.741556 -1.5708 0.649262 1.43614</pose>
        <inertial>
          <pose frame=''>0.044 -0.0015 0 0 -0 0</pose>
          <mass>0.02</mass>
          <inertia>
            <ixx>1.62499e-06</ixx>
            <ixy>6.6e-07</ixy>
            <ixz>0</ixz>
            <iyy>1.126e-05</iyy>
            <iyz>0</iyz>
            <izz>9.885e-06</izz>
          </inertia>
        </inertial>
        <collision name='j2s7s300_link_finger_3_collision'>
          <pose frame=''>0 0 0 0 -0 0</pose>
          <geometry>
            <mesh>
              <scale>1 1 1</scale>
              <uri>/home/xkx/JCAR_V1_ws/src/kinova_description/meshes/finger_proximal.dae</uri>
            </mesh>
          </geometry>
          <max_contacts>10</max_contacts>
          <surface>
            <contact>
              <ode/>
            </contact>
            <bounce/>
            <friction>
              <torsional>
                <ode/>
              </torsional>
              <ode/>
            </friction>
          </surface>
        </collision>
        <collision name='j2s7s300_link_finger_3_fixed_joint_lump__j2s7s300_link_finger_tip_3_collision_1'>
          <pose frame=''>0.044 -0.003 0 0 -0 0</pose>
          <geometry>
            <mesh>
              <scale>1 1 1</scale>
              <uri>/home/xkx/JCAR_V1_ws/src/kinova_description/meshes/finger_distal.dae</uri>
            </mesh>
          </geometry>
          <max_contacts>10</max_contacts>
          <surface>
            <contact>
              <ode/>
            </contact>
            <bounce/>
            <friction>
              <torsional>
                <ode/>
              </torsional>
              <ode/>
            </friction>
          </surface>
        </collision>
        <visual name='j2s7s300_link_finger_3_visual'>
          <pose frame=''>0 0 0 0 -0 0</pose>
          <geometry>
            <mesh>
              <scale>1 1 1</scale>
              <uri>/home/xkx/JCAR_V1_ws/src/kinova_description/meshes/finger_proximal.dae</uri>
            </mesh>
          </geometry>
        </visual>
        <visual name='j2s7s300_link_finger_3_fixed_joint_lump__j2s7s300_link_finger_tip_3_visual_1'>
          <pose frame=''>0.044 -0.003 0 0 -0 0</pose>
          <geometry>
            <mesh>
              <scale>1 1 1</scale>
              <uri>/home/xkx/JCAR_V1_ws/src/kinova_description/meshes/finger_distal.dae</uri>
            </mesh>
          </geometry>
        </visual>
        <self_collide>0</self_collide>
        <kinematic>0</kinematic>
      </link>
      <joint name='j2s7s300_joint_finger_3' type='revolute'>
        <child>j2s7s300_link_finger_3</child>
        <parent>j2s7s300_link_7</parent>
        <axis>
          <xyz>-0.990948 0.134249 0</xyz>
          <limit>
            <lower>0</lower>
            <upper>2</upper>
            <effort>2000</effort>
            <velocity>1</velocity>
          </limit>
          <dynamics>
            <spring_reference>0</spring_reference>
            <spring_stiffness>0</spring_stiffness>
          </dynamics>
          <use_parent_model_frame>1</use_parent_model_frame>
        </axis>
      </joint>
      <static>0</static>
      <plugin name='gazebo_ros_control' filename='libgazebo_ros_control.so'>
        <robotNamespace>j2s7s300</robotNamespace>
        <robotSimType>gazebo_ros_control/DefaultRobotHWSim</robotSimType>
      </plugin>
      <pose frame=''>0 0 0 0 -0 0</pose>
    </model>
    <model name='cube'>
      <static>1</static>
      <link name='link'>
        <pose frame=''>0 0 0 0 -0 0</pose>
        <inertial>
          <mass>0.07</mass>
          <inertia>
            <ixx>1e-05</ixx>
            <iyy>1e-05</iyy>
            <izz>1e-05</izz>
            <ixy>0</ixy>
            <ixz>0</ixz>
            <iyz>0</iyz>
          </inertia>
        </inertial>
        <collision name='collision'>
          <geometry>
            <mesh>
              <scale>0.01 0.01 0.01</scale>
              <uri>model://cube/meshes/cube.dae</uri>
            </mesh>
          </geometry>
          <surface>
            <contact>
              <ode>
                <max_vel>0.1</max_vel>
                <min_depth>0.001</min_depth>
              </ode>
            </contact>
            <bounce/>
            <friction>
              <torsional>
                <ode/>
              </torsional>
              <ode/>
            </friction>
          </surface>
          <max_contacts>10</max_contacts>
        </collision>
        <visual name='visual'>
          <geometry>
            <mesh>
              <scale>0.01 0.01 0.01</scale>
              <uri>model://cube/meshes/cube.dae</uri>
            </mesh>
          </geometry>
          <material>
            <script>
              <name>Gazebo/WoodTile</name>
              <uri>file://media/materials/scripts/gazebo.material</uri>
            </script>
          </material>
        </visual>
        <self_collide>0</self_collide>
        <kinematic>0</kinematic>
      </link>
      <pose frame=''>0.364588 -0.722408 0 0 -0 0</pose>
    </model>
    <model name='cube_0'>
      <static>1</static>
      <link name='link'>
        <pose frame=''>0 0 0 0 -0 0</pose>
        <inertial>
          <mass>0.07</mass>
          <inertia>
            <ixx>1e-05</ixx>
            <iyy>1e-05</iyy>
            <izz>1e-05</izz>
            <ixy>0</ixy>
            <ixz>0</ixz>
            <iyz>0</iyz>
          </inertia>
        </inertial>
        <collision name='collision'>
          <geometry>
            <mesh>
              <scale>0.01 0.01 0.01</scale>
              <uri>model://cube/meshes/cube.dae</uri>
            </mesh>
          </geometry>
          <surface>
            <contact>
              <ode>
                <max_vel>0.1</max_vel>
                <min_depth>0.001</min_depth>
              </ode>
            </contact>
            <bounce/>
            <friction>
              <torsional>
                <ode/>
              </torsional>
              <ode/>
            </friction>
          </surface>
          <max_contacts>10</max_contacts>
        </collision>
        <visual name='visual'>
          <geometry>
            <mesh>
              <scale>0.01 0.01 0.01</scale>
              <uri>model://cube/meshes/cube.dae</uri>
            </mesh>
          </geometry>
          <material>
            <script>
              <name>Gazebo/WoodTile</name>
              <uri>file://media/materials/scripts/gazebo.material</uri>
            </script>
          </material>
        </visual>
        <self_collide>0</self_collide>
        <kinematic>0</kinematic>
      </link>
      <pose frame=''>1.70396 -0.834942 0 0 -0 0</pose>
    </model>
    <model name='cube_1'>
      <static>1</static>
      <link name='link'>
        <pose frame=''>0 0 0 0 -0 0</pose>
        <inertial>
          <mass>0.07</mass>
          <inertia>
            <ixx>1e-05</ixx>
            <iyy>1e-05</iyy>
            <izz>1e-05</izz>
            <ixy>0</ixy>
            <ixz>0</ixz>
            <iyz>0</iyz>
          </inertia>
        </inertial>
        <collision name='collision'>
          <geometry>
            <mesh>
              <scale>0.01 0.01 0.01</scale>
              <uri>model://cube/meshes/cube.dae</uri>
            </mesh>
          </geometry>
          <surface>
            <contact>
              <ode>
                <max_vel>0.1</max_vel>
                <min_depth>0.001</min_depth>
              </ode>
            </contact>
            <bounce/>
            <friction>
              <torsional>
                <ode/>
              </torsional>
              <ode/>
            </friction>
          </surface>
          <max_contacts>10</max_contacts>
        </collision>
        <visual name='visual'>
          <geometry>
            <mesh>
              <scale>0.01 0.01 0.01</scale>
              <uri>model://cube/meshes/cube.dae</uri>
            </mesh>
          </geometry>
          <material>
            <script>
              <name>Gazebo/WoodTile</name>
              <uri>file://media/materials/scripts/gazebo.material</uri>
            </script>
          </material>
        </visual>
        <self_collide>0</self_collide>
        <kinematic>0</kinematic>
      </link>
      <pose frame=''>1.43244 -1.19369 0 0 -0 0</pose>
    </model>
    <model name='cube_2'>
      <static>1</static>
      <link name='link'>
        <pose frame=''>0 0 0 0 -0 0</pose>
        <inertial>
          <mass>0.07</mass>
          <inertia>
            <ixx>1e-05</ixx>
            <iyy>1e-05</iyy>
            <izz>1e-05</izz>
            <ixy>0</ixy>
            <ixz>0</ixz>
            <iyz>0</iyz>
          </inertia>
        </inertial>
        <collision name='collision'>
          <geometry>
            <mesh>
              <scale>0.01 0.01 0.01</scale>
              <uri>model://cube/meshes/cube.dae</uri>
            </mesh>
          </geometry>
          <surface>
            <contact>
              <ode>
                <max_vel>0.1</max_vel>
                <min_depth>0.001</min_depth>
              </ode>
            </contact>
            <bounce/>
            <friction>
              <torsional>
                <ode/>
              </torsional>
              <ode/>
            </friction>
          </surface>
          <max_contacts>10</max_contacts>
        </collision>
        <visual name='visual'>
          <geometry>
            <mesh>
              <scale>0.01 0.01 0.01</scale>
              <uri>model://cube/meshes/cube.dae</uri>
            </mesh>
          </geometry>
          <material>
            <script>
              <name>Gazebo/WoodTile</name>
              <uri>file://media/materials/scripts/gazebo.material</uri>
            </script>
          </material>
        </visual>
        <self_collide>0</self_collide>
        <kinematic>0</kinematic>
      </link>
      <pose frame=''>1.73543 -1.01663 0 0 -0 0</pose>
    </model>
    <model name='cube_4'>
      <static>1</static>
      <link name='link'>
        <pose frame=''>0 0 0 0 -0 0</pose>
        <inertial>
          <mass>0.07</mass>
          <inertia>
            <ixx>1e-05</ixx>
            <iyy>1e-05</iyy>
            <izz>1e-05</izz>
            <ixy>0</ixy>
            <ixz>0</ixz>
            <iyz>0</iyz>
          </inertia>
        </inertial>
        <collision name='collision'>
          <geometry>
            <mesh>
              <scale>0.01 0.01 0.01</scale>
              <uri>model://cube/meshes/cube.dae</uri>
            </mesh>
          </geometry>
          <surface>
            <contact>
              <ode>
                <max_vel>0.1</max_vel>
                <min_depth>0.001</min_depth>
              </ode>
            </contact>
            <bounce/>
            <friction>
              <torsional>
                <ode/>
              </torsional>
              <ode/>
            </friction>
          </surface>
          <max_contacts>10</max_contacts>
        </collision>
        <visual name='visual'>
          <geometry>
            <mesh>
              <scale>0.01 0.01 0.01</scale>
              <uri>model://cube/meshes/cube.dae</uri>
            </mesh>
          </geometry>
          <material>
            <script>
              <name>Gazebo/WoodTile</name>
              <uri>file://media/materials/scripts/gazebo.material</uri>
            </script>
          </material>
        </visual>
        <self_collide>0</self_collide>
        <kinematic>0</kinematic>
      </link>
      <pose frame=''>1.78129 -0.593492 0 0 -0 0</pose>
    </model>
    <model name='cube_5'>
      <static>1</static>
      <link name='link'>
        <pose frame=''>0 0 0 0 -0 0</pose>
        <inertial>
          <mass>0.07</mass>
          <inertia>
            <ixx>1e-05</ixx>
            <iyy>1e-05</iyy>
            <izz>1e-05</izz>
            <ixy>0</ixy>
            <ixz>0</ixz>
            <iyz>0</iyz>
          </inertia>
        </inertial>
        <collision name='collision'>
          <geometry>
            <mesh>
              <scale>0.01 0.01 0.01</scale>
              <uri>model://cube/meshes/cube.dae</uri>
            </mesh>
          </geometry>
          <surface>
            <contact>
              <ode>
                <max_vel>0.1</max_vel>
                <min_depth>0.001</min_depth>
              </ode>
            </contact>
            <bounce/>
            <friction>
              <torsional>
                <ode/>
              </torsional>
              <ode/>
            </friction>
          </surface>
          <max_contacts>10</max_contacts>
        </collision>
        <visual name='visual'>
          <geometry>
            <mesh>
              <scale>0.01 0.01 0.01</scale>
              <uri>model://cube/meshes/cube.dae</uri>
            </mesh>
          </geometry>
          <material>
            <script>
              <name>Gazebo/WoodTile</name>
              <uri>file://media/materials/scripts/gazebo.material</uri>
            </script>
          </material>
        </visual>
        <self_collide>0</self_collide>
        <kinematic>0</kinematic>
      </link>
      <pose frame=''>1.35912 -0.546381 0 0 -0 0</pose>
    </model>
    <state world_name='default'>
      <sim_time>204 125000000</sim_time>
      <real_time>216 288446640</real_time>
      <wall_time>1532618883 873470365</wall_time>
      <iterations>204125</iterations>
      <model name='cube'>
        <pose frame=''>0.242724 -0.212274 0.737411 0 -0 0</pose>
        <scale>1 1 1</scale>
        <link name='link'>
          <pose frame=''>0.242724 -0.212274 0.737411 0 -0 0</pose>
          <velocity>0 0 0 0 -0 0</velocity>
          <acceleration>0 0 0 0 -0 0</acceleration>
          <wrench>0 0 0 0 -0 0</wrench>
        </link>
      </model>
      <model name='cube_0'>
        <pose frame=''>0.498328 -0.006002 1.54676 0 -0 0</pose>
        <scale>1 1 1</scale>
        <link name='link'>
          <pose frame=''>0.498328 -0.006002 1.54676 0 -0 0</pose>
          <velocity>0 0 0 0 -0 0</velocity>
          <acceleration>0 0 0 0 -0 0</acceleration>
          <wrench>0 0 0 0 -0 0</wrench>
        </link>
      </model>
      <model name='cube_1'>
        <pose frame=''>0.528526 -0.108216 1.34639 0 -0 0</pose>
        <scale>1 1 1</scale>
        <link name='link'>
          <pose frame=''>0.528526 -0.108216 1.34639 0 -0 0</pose>
          <velocity>0 0 0 0 -0 0</velocity>
          <acceleration>0 0 0 0 -0 0</acceleration>
          <wrench>0 0 0 0 -0 0</wrench>
        </link>
      </model>
      <model name='cube_2'>
        <pose frame=''>0.425756 0.079964 1.81708 0 -0 0</pose>
        <scale>1 1 1</scale>
        <link name='link'>
          <pose frame=''>0.425756 0.079964 1.81708 0 -0 0</pose>
          <velocity>0 0 0 0 -0 0</velocity>
          <acceleration>0 0 0 0 -0 0</acceleration>
          <wrench>0 0 0 0 -0 0</wrench>
        </link>
      </model>
      <model name='cube_4'>
        <pose frame=''>0.286568 -0.227823 0.9801 0 -0 0</pose>
        <scale>1 1 1</scale>
        <link name='link'>
          <pose frame=''>0.286568 -0.227823 0.9801 0 -0 0</pose>
          <velocity>0 0 0 0 -0 0</velocity>
          <acceleration>0 0 0 0 -0 0</acceleration>
          <wrench>0 0 0 0 -0 0</wrench>
        </link>
      </model>
      <model name='cube_5'>
        <pose frame=''>0.449938 -0.198499 1.13913 0 -0 0</pose>
        <scale>1 1 1</scale>
        <link name='link'>
          <pose frame=''>0.449938 -0.198499 1.13913 0 -0 0</pose>
          <velocity>0 0 0 0 -0 0</velocity>
          <acceleration>0 0 0 0 -0 0</acceleration>
          <wrench>0 0 0 0 -0 0</wrench>
        </link>
      </model>
      <model name='ground_plane'>
        <pose frame=''>0 0 0 0 -0 0</pose>
        <scale>1 1 1</scale>
        <link name='link'>
          <pose frame=''>0 0 0 0 -0 0</pose>
          <velocity>0 0 0 0 -0 0</velocity>
          <acceleration>0 0 0 0 -0 0</acceleration>
          <wrench>0 0 0 0 -0 0</wrench>
        </link>
      </model>
      <model name='object_on_table'>
        <pose frame=''>0.000119 0.000134 4e-06 0.000112 -9.8e-05 -4.6e-05</pose>
        <scale>1 1 1</scale>
        <link name='j2s7s300_link_1'>
          <pose frame=''>0.01852 0.339028 0.940288 -3.1415 -8.5e-05 -0.091307</pose>
          <velocity>-0.003153 -0.004969 0.007553 -0.016448 0.018328 -0.218415</velocity>
          <acceleration>0.090842 -0.001936 -0.000285 0.012748 -0.025334 0.41395</acceleration>
          <wrench>0.067922 -0.001447 -0.000213 0 -0 0</wrench>
        </link>
        <link name='j2s7s300_link_2'>
          <pose frame=''>0.018365 0.337425 1.05904 -1.57071 0.269097 -0.091286</pose>
          <velocity>0.039902 -0.001396 -0.003448 -0.053439 -0.393733 -0.21863</velocity>
          <acceleration>2.10169 -1.41377 -0.653548 -2.97232 1.02334 -2.33114</acceleration>
          <wrench>1.7753 -1.19421 -0.552052 0 -0 0</wrench>
        </link>
        <link name='j2s7s300_link_3'>
          <pose frame=''>0.072639 0.332439 1.25667 3.13481 0.269011 -0.117125</pose>
          <velocity>-0.039629 -0.002729 0.018277 -0.079874 -0.390888 -0.313552</velocity>
          <acceleration>6.37501 -4.22482 -1.93835 -0.995407 -0.101495 0.742549</acceleration>
          <wrench>5.38497 -3.56871 -1.63732 0 -0 0</wrench>
        </link>
        <link name='j2s7s300_link_4'>
          <pose frame=''>0.126912 0.327452 1.45429 1.56426 0.056982 -0.115693</pose>
          <velocity>-0.064786 -0.016758 0.045486 -0.17168 -1.18343 -0.308244</velocity>
          <acceleration>3.39072 -4.4622 -2.4432 -2.4173 -1.27209 -0.717937</acceleration>
          <wrench>2.29315 -3.01779 -1.65234 0 -0 0</wrench>
        </link>
        <link name='j2s7s300_link_5'>
          <pose frame=''>0.140108 0.338761 1.66118 -3.13507 0.056984 0.11264</pose>
          <velocity>-0.335509 0.018355 0.060003 -0.148062 -1.18353 0.097402</velocity>
          <acceleration>-9.35608 -1.65901 -1.87083 0.180894 -0.004009 1.56334</acceleration>
          <wrench>-4.33187 -0.76812 -0.866195 0 -0 0</wrench>
        </link>
        <link name='j2s7s300_link_6'>
          <pose frame=''>0.146056 0.338754 1.76476 1.57754 0.268044 0.11405</pose>
          <velocity>-0.469178 0.228419 0.042057 3.0626 -1.35361 -3.04777</velocity>
          <acceleration>-13.6051 0.507281 -1.9206 -1.13825 0.833487 -2.15672</acceleration>
          <wrench>-6.29918 0.234871 -0.889236 0 -0 0</wrench>
        </link>
        <link name='j2s7s300_link_7'>
          <pose frame=''>0.173435 0.341186 1.8648 3.08656 -0.262549 -2.84385</pose>
          <velocity>-0.625929 -0.085057 0.103379 -3.11436 -1.36364 -2.66441</velocity>
          <acceleration>-14.6512 3.74884 -2.01968 2.15718 -0.055952 0.705308</acceleration>
          <wrench>-10.6514 2.7254 -1.46831 0 -0 0</wrench>
        </link>
        <link name='j2s7s300_link_finger_1'>
          <pose frame=''>0.19239 0.373055 1.97776 -2.49982 -1.26305 -0.149798</pose>
          <velocity>-0.865688 0.210961 0.14254 2.84117 -1.17908 -2.56937</velocity>
          <acceleration>-8.97967 -1.76562 -5.30531 3.0061 -1.47826 0.482074</acceleration>
          <wrench>-0.179593 -0.035312 -0.106106 0 -0 0</wrench>
        </link>
        <link name='j2s7s300_link_finger_2'>
          <pose frame=''>0.190743 0.311619 1.97986 -0.254665 -1.29355 0.370776</pose>
          <velocity>-0.839754 -0.024022 0.142352 -2.68403 -1.41092 -2.78398</velocity>
          <acceleration>-18.672 15.3656 -1.05551 -2.34945 1.06774 -0.312039</acceleration>
          <wrench>-0.373441 0.307311 -0.02111 0 -0 0</wrench>
        </link>
        <link name='j2s7s300_link_finger_3'>
          <pose frame=''>0.231846 0.324232 1.9683 0.094879 -1.32175 0.390119</pose>
          <velocity>-0.83179 0.229991 0.202741 2.91515 -1.23053 -2.59151</velocity>
          <acceleration>-10.924 -7.56304 -1.7322 -2.40128 -1.39431 -2.83209</acceleration>
          <wrench>-0.218481 -0.151261 -0.034644 0 -0 0</wrench>
        </link>
        <link name='table_base'>
          <pose frame=''>9.2e-05 0.000103 0.273004 0.000112 -9.8e-05 -4.6e-05</pose>
          <velocity>-0.03171 -0.035473 -0.00143 -0.022461 0.019663 0.009293</velocity>
          <acceleration>1e-06 3e-06 0 0.000146 0.000148 3.9e-05</acceleration>
          <wrench>4.21251 10.7971 0.084889 0 -0 0</wrench>
        </link>
        <link name='table_base2'>
          <pose frame=''>0.000114 0.850106 0.273003 0.000116 -0.000122 -4.2e-05</pose>
          <velocity>-0.039277 -0.036533 -0.001318 -0.02316 0.024475 0.008463</velocity>
          <acceleration>0 0 0 0.000208 0.000189 7.9e-05</acceleration>
          <wrench>1.14185 1.15492 0.003711 0 -0 0</wrench>
        </link>
      </model>
      <light name='sun'>
        <pose frame=''>0 0 10 0 -0 0</pose>
      </light>
    </state>
    <gui fullscreen='0'>
      <camera name='user_camera'>
        <pose frame=''>0.888076 -1.81832 2.33833 0 0.381797 1.948</pose>
        <view_controller>orbit</view_controller>
        <projection_type>perspective</projection_type>
      </camera>
    </gui>
  </world>
</sdf>
